Workbook

Sheet ADCL Codes Updated
A1: S.No | B1: Project | C1: Nature of work | D1: Department | E1: Indent Date | F1: Role | G1: Total Req | H1: Required By Date | I1: Interview Panel | J1: HR SPOC | K1: Job ID | M1: Level | N1: Interview Pipeline | O1: Second Level Interviews | P1: Offer Negotiation in Process | Q1: Offer Released | R1: Joined | S1: Interview Rejected | T1: Candidate Not Interested | U1: Total Sourcing | V1: Open | W1: Exp Offer Release & further stages Count | X1: Exp Salary Negotiation & Further stages | Y1: Exp Interview Pipeline Count | Z1: Pending Offer Released & further | AA1: Pending Salary Negotiation & Further | AB1: Pending Interview Pipeline & further | AC1: Target Date to close all offers | AD1: Target Date to complete interviews | AE1: Target Date to complete sourcing | AF1: Weeks Remaining to complete offers | AG1: Weeks Remaining to complete interviews | AH1: Weeks Remaining to complete sourcing | AI1: Exp Joinings in Apr 1st Wk | AJ1: Exp Joinings in Apr 2nd Wk | AK1: Exp Joinings in Apr 3rd Wk | AL1: Exp Joinings in Apr 4th Wk | AM1: Exp Joinings in May 1st Wk
A2: =ROW()-1 -> 1 | B2: ADCL | C2: General | E2: 45745 | F2: VP/AVP/SGM | G2: 2 | H2: 45777 | I2: Mr. Raghu Rama Raju | J2: Mr. Ravindra Varma | K2: ANY-113 | L2: ADCL-01 | M2: APM & Above | N2: =COUNTIFS('Profiles Tracker'!E:E,#REF!,'Profiles Tracker'!G:G,"Profile shared with Interviewer") -> 0 | O2: =COUNTIFS('Profiles Tracker'!E:E,#REF!,'Profiles Tracker'!G:G,"Shortlisted for next round of interview") -> 0 | P2: =COUNTIFS('Profiles Tracker'!E:E,#REF!,'Profiles Tracker'!G:G,P$1) -> 0 | Q2: =COUNTIFS('Profiles Tracker'!E:E,#REF!,'Profiles Tracker'!G:G,Q$1) -> 0 | R2: =COUNTIFS('Profiles Tracker'!E:E,#REF!,'Profiles Tracker'!G:G,R$1) -> 0 | S2: =COUNTIFS('Profiles Tracker'!E:E,#REF!,'Profiles Tracker'!G:G,"Interview Done",'Profiles Tracker'!O:O,"Rejected") -> 0 | T2: =COUNTIFS('Profiles Tracker'!E:E,#REF!,'Profiles Tracker'!G:G,T$1) -> 0 | U2: =N2+P2+Q2+R2+S2+T2 -> 0 | V2: =IF((G2-R2-Q2)<1,0,G2-R2-Q2) -> 2 | W2: =FLOOR(G2,1) -> 2 | X2: =FLOOR(W2,1) -> 2 | Y2: =X2*3 -> 6 | Z2: =IF(W2-SUM(Q2:R2)<1,0,W2-SUM(Q2:R2)) -> 2 | AA2: =IF(X2-SUM(P2:R2)<1,0,X2-SUM(P2:R2)) -> 2 | AB2: =IF(AA2*3-N2<1,0,AA2*3-N2) -> 6 | AC2: =IF(M2="APM Below",H2-45,IF(M2="APM & Above", H2-60,H2-90)) -> 45717 | AD2: =IFERROR(AC2-5,"NA") -> 45712 | AE2: =IFERROR(AD2-7,"NA") -> 45705 | AF2: =CEILING((AC2-TODAY())/7,1) -> -56 | AG2: =CEILING((AD2-TODAY())/7,1) -> -57 | AH2: =CEILING((AE2-TODAY())/7,1) -> -58 | AI2: =COUNTIFS('Profiles Tracker'!E:E,#REF!,'Profiles Tracker'!G:G,Q$1,'Profiles Tracker'!#REF!,"Week 14") -> #REF! | AJ2: =COUNTIFS('Profiles Tracker'!E:E,#REF!,'Profiles Tracker'!G:G,Q$1,'Profiles Tracker'!#REF!,"Week 15") -> #REF! | AK2: =COUNTIFS('Profiles Tracker'!E:E,#REF!,'Profiles Tracker'!G:G,Q$1,'Profiles Tracker'!#REF!,"Week 16") -> #REF! | AL2: =COUNTIFS('Profiles Tracker'!E:E,#REF!,'Profiles Tracker'!G:G,Q$1,'Profiles Tracker'!#REF!,"Week 17") -> #REF! | AM2: =COUNTIFS('Profiles Tracker'!E:E,#REF!,'Profiles Tracker'!G:G,Q$1,'Profiles Tracker'!#REF!,"Week 18") -> #REF!
A3: =ROW()-1 -> 2 | B3: ADCL | C3: General | E3: 45668 | F3: General Manager | G3: 1 | H3: 45716 | I3: Mr. Raghu Rama Raju | J3: Mr. Ravindra Varma | K3: ANY-01 | L3: ADCL-02 | M3: APM & Above | N3: =COUNTIFS('Profiles Tracker'!E:E,#REF!,'Profiles Tracker'!G:G,"Profile shared with Interviewer") -> 0 | O3: =COUNTIFS('Profiles Tracker'!E:E,#REF!,'Profiles Tracker'!G:G,"Shortlisted for next round of interview") -> 0 | P3: =COUNTIFS('Profiles Tracker'!E:E,#REF!,'Profiles Tracker'!G:G,P$1) -> 0 | Q3: =COUNTIFS('Profiles Tracker'!E:E,#REF!,'Profiles Tracker'!G:G,Q$1) -> 0 | R3: =COUNTIFS('Profiles Tracker'!E:E,#REF!,'Profiles Tracker'!G:G,R$1) -> 0 | S3: =COUNTIFS('Profiles Tracker'!E:E,#REF!,'Profiles Tracker'!G:G,"Interview Done",'Profiles Tracker'!O:O,"Rejected") -> 0 | T3: =COUNTIFS('Profiles Tracker'!E:E,#REF!,'Profiles Tracker'!G:G,T$1) -> 0 | U3: =N3+P3+Q3+R3+S3+T3 -> 0 | V3: =IF((G3-R3-Q3)<1,0,G3-R3-Q3) -> 1 | W3: =FLOOR(G3,1) -> 1 | X3: =FLOOR(W3,1) -> 1 | Y3: =X3*3 -> 3 | Z3: =IF(W3-SUM(Q3:R3)<1,0,W3-SUM(Q3:R3)) -> 1 | AA3: =IF(X3-SUM(P3:R3)<1,0,X3-SUM(P3:R3)) -> 1 | AB3: =IF(AA3*3-N3<1,0,AA3*3-N3) -> 3 | AC3: =IF(M3="APM Below",H3-45,IF(M3="APM & Above", H3-60,H3-90)) -> 45656 | AD3: =IFERROR(AC3-5,"NA") -> 45651 | AE3: =IFERROR(AD3-7,"NA") -> 45644 | AF3: =CEILING((AC3-TODAY())/7,1) -> -65 | AG3: =CEILING((AD3-TODAY())/7,1) -> -66 | AH3: =CEILING((AE3-TODAY())/7,1) -> -67 | AI3: =COUNTIFS('Profiles Tracker'!E:E,#REF!,'Profiles Tracker'!G:G,Q$1,'Profiles Tracker'!#REF!,"Week 14") -> #REF! | AJ3: =COUNTIFS('Profiles Tracker'!E:E,#REF!,'Profiles Tracker'!G:G,Q$1,'Profiles Tracker'!#REF!,"Week 15") -> #REF! | AK3: =COUNTIFS('Profiles Tracker'!E:E,#REF!,'Profiles Tracker'!G:G,Q$1,'Profiles Tracker'!#REF!,"Week 16") -> #REF! | AL3: =COUNTIFS('Profiles Tracker'!E:E,#REF!,'Profiles Tracker'!G:G,Q$1,'Profiles Tracker'!#REF!,"Week 17") -> #REF! | AM3: =COUNTIFS('Profiles Tracker'!E:E,#REF!,'Profiles Tracker'!G:G,Q$1,'Profiles Tracker'!#REF!,"Week 18") -> #REF!
A4: =ROW()-1 -> 3 | B4: ADCL | C4: Roads | E4: 45668 | F4: PM ( Structures & Roads ) | G4: 9 | H4: 45716 | I4: Mr. Raghu Rama Raju | J4: Mr. Ravindra Varma | K4: ANY-02 | L4: ADCL-03 | M4: APM & Above | N4: =COUNTIFS('Profiles Tracker'!E:E,#REF!,'Profiles Tracker'!G:G,"Profile shared with Interviewer") -> 0 | O4: =COUNTIFS('Profiles Tracker'!E:E,#REF!,'Profiles Tracker'!G:G,"Shortlisted for next round of interview") -> 0 | P4: =COUNTIFS('Profiles Tracker'!E:E,#REF!,'Profiles Tracker'!G:G,P$1) -> 0 | Q4: =COUNTIFS('Profiles Tracker'!E:E,#REF!,'Profiles Tracker'!G:G,Q$1) -> 0 | R4: =COUNTIFS('Profiles Tracker'!E:E,#REF!,'Profiles Tracker'!G:G,R$1) -> 0 | S4: =COUNTIFS('Profiles Tracker'!E:E,#REF!,'Profiles Tracker'!G:G,"Interview Done",'Profiles Tracker'!O:O,"Rejected") -> 0 | T4: =COUNTIFS('Profiles Tracker'!E:E,#REF!,'Profiles Tracker'!G:G,T$1) -> 0 | U4: =N4+P4+Q4+R4+S4+T4 -> 0 | V4: =IF((G4-R4-Q4)<1,0,G4-R4-Q4) -> 9 | W4: =FLOOR(G4,1) -> 9 | X4: =FLOOR(W4,1) -> 9 | Y4: =X4*3 -> 27 | Z4: =IF(W4-SUM(Q4:R4)<1,0,W4-SUM(Q4:R4)) -> 9 | AA4: =IF(X4-SUM(P4:R4)<1,0,X4-SUM(P4:R4)) -> 9 | AB4: =IF(AA4*3-N4<1,0,AA4*3-N4) -> 27 | AC4: =IF(M4="APM Below",H4-45,IF(M4="APM & Above", H4-60,H4-90)) -> 45656 | AD4: =IFERROR(AC4-5,"NA") -> 45651 | AE4: =IFERROR(AD4-7,"NA") -> 45644 | AF4: =CEILING((AC4-TODAY())/7,1) -> -65 | AG4: =CEILING((AD4-TODAY())/7,1) -> -66 | AH4: =CEILING((AE4-TODAY())/7,1) -> -67 | AI4: =COUNTIFS('Profiles Tracker'!E:E,#REF!,'Profiles Tracker'!G:G,Q$1,'Profiles Tracker'!#REF!,"Week 14") -> #REF! | AJ4: =COUNTIFS('Profiles Tracker'!E:E,#REF!,'Profiles Tracker'!G:G,Q$1,'Profiles Tracker'!#REF!,"Week 15") -> #REF! | AK4: =COUNTIFS('Profiles Tracker'!E:E,#REF!,'Profiles Tracker'!G:G,Q$1,'Profiles Tracker'!#REF!,"Week 16") -> #REF! | AL4: =COUNTIFS('Profiles Tracker'!E:E,#REF!,'Profiles Tracker'!G:G,Q$1,'Profiles Tracker'!#REF!,"Week 17") -> #REF! | AM4: =COUNTIFS('Profiles Tracker'!E:E,#REF!,'Profiles Tracker'!G:G,Q$1,'Profiles Tracker'!#REF!,"Week 18") -> #REF!
A5: =ROW()-1 -> 4 | B5: ADCL | C5: Structures | E5: 45668 | F5: DPM Structures | G5: 11 | H5: 45716 | I5: Mr. Raghu Rama Raju | J5: Mr. Ravindra Varma | K5: ANY-03 | L5: ADCL-04 | M5: APM & Above | N5: =COUNTIFS('Profiles Tracker'!E:E,#REF!,'Profiles Tracker'!G:G,"Profile shared with Interviewer") -> 0 | O5: =COUNTIFS('Profiles Tracker'!E:E,#REF!,'Profiles Tracker'!G:G,"Shortlisted for next round of interview") -> 0 | P5: =COUNTIFS('Profiles Tracker'!E:E,#REF!,'Profiles Tracker'!G:G,P$1) -> 0 | Q5: =COUNTIFS('Profiles Tracker'!E:E,#REF!,'Profiles Tracker'!G:G,Q$1) -> 0 | R5: =COUNTIFS('Profiles Tracker'!E:E,#REF!,'Profiles Tracker'!G:G,R$1) -> 0 | S5: =COUNTIFS('Profiles Tracker'!E:E,#REF!,'Profiles Tracker'!G:G,"Interview Done",'Profiles Tracker'!O:O,"Rejected") -> 0 | T5: =COUNTIFS('Profiles Tracker'!E:E,#REF!,'Profiles Tracker'!G:G,T$1) -> 0 | U5: =N5+P5+Q5+R5+S5+T5 -> 0 | V5: =IF((G5-R5-Q5)<1,0,G5-R5-Q5) -> 11 | W5: =FLOOR(G5,1) -> 11 | X5: =FLOOR(W5,1) -> 11 | Y5: =X5*3 -> 33 | Z5: =IF(W5-SUM(Q5:R5)<1,0,W5-SUM(Q5:R5)) -> 11 | AA5: =IF(X5-SUM(P5:R5)<1,0,X5-SUM(P5:R5)) -> 11 | AB5: =IF(AA5*3-N5<1,0,AA5*3-N5) -> 33 | AC5: =IF(M5="APM Below",H5-45,IF(M5="APM & Above", H5-60,H5-90)) -> 45656 | AD5: =IFERROR(AC5-5,"NA") -> 45651 | AE5: =IFERROR(AD5-7,"NA") -> 45644 | AF5: =CEILING((AC5-TODAY())/7,1) -> -65 | AG5: =CEILING((AD5-TODAY())/7,1) -> -66 | AH5: =CEILING((AE5-TODAY())/7,1) -> -67 | AI5: =COUNTIFS('Profiles Tracker'!E:E,#REF!,'Profiles Tracker'!G:G,Q$1,'Profiles Tracker'!#REF!,"Week 14") -> #REF! | AJ5: =COUNTIFS('Profiles Tracker'!E:E,#REF!,'Profiles Tracker'!G:G,Q$1,'Profiles Tracker'!#REF!,"Week 15") -> #REF! | AK5: =COUNTIFS('Profiles Tracker'!E:E,#REF!,'Profiles Tracker'!G:G,Q$1,'Profiles Tracker'!#REF!,"Week 16") -> #REF! | AL5: =COUNTIFS('Profiles Tracker'!E:E,#REF!,'Profiles Tracker'!G:G,Q$1,'Profiles Tracker'!#REF!,"Week 17") -> #REF! | AM5: =COUNTIFS('Profiles Tracker'!E:E,#REF!,'Profiles Tracker'!G:G,Q$1,'Profiles Tracker'!#REF!,"Week 18") -> #REF!
A6: =ROW()-1 -> 5 | B6: ADCL | C6: Roads | E6: 45668 | F6: DPM Roads | G6: 13 | H6: 45716 | I6: Mr. Raghu Rama Raju | J6: Mr. Ravindra Varma | K6: ANY-04 | L6: ADCL-05 | M6: APM & Above | N6: =COUNTIFS('Profiles Tracker'!E:E,#REF!,'Profiles Tracker'!G:G,"Profile shared with Interviewer") -> 0 | O6: =COUNTIFS('Profiles Tracker'!E:E,#REF!,'Profiles Tracker'!G:G,"Shortlisted for next round of interview") -> 0 | P6: =COUNTIFS('Profiles Tracker'!E:E,#REF!,'Profiles Tracker'!G:G,P$1) -> 0 | Q6: =COUNTIFS('Profiles Tracker'!E:E,#REF!,'Profiles Tracker'!G:G,Q$1) -> 0 | R6: =COUNTIFS('Profiles Tracker'!E:E,#REF!,'Profiles Tracker'!G:G,R$1) -> 0 | S6: =COUNTIFS('Profiles Tracker'!E:E,#REF!,'Profiles Tracker'!G:G,"Interview Done",'Profiles Tracker'!O:O,"Rejected") -> 0 | T6: =COUNTIFS('Profiles Tracker'!E:E,#REF!,'Profiles Tracker'!G:G,T$1) -> 0 | U6: =N6+P6+Q6+R6+S6+T6 -> 0 | V6: =IF((G6-R6-Q6)<1,0,G6-R6-Q6) -> 13 | W6: =FLOOR(G6,1) -> 13 | X6: =FLOOR(W6,1) -> 13 | Y6: =X6*3 -> 39 | Z6: =IF(W6-SUM(Q6:R6)<1,0,W6-SUM(Q6:R6)) -> 13 | AA6: =IF(X6-SUM(P6:R6)<1,0,X6-SUM(P6:R6)) -> 13 | AB6: =IF(AA6*3-N6<1,0,AA6*3-N6) -> 39 | AC6: =IF(M6="APM Below",H6-45,IF(M6="APM & Above", H6-60,H6-90)) -> 45656 | AD6: =IFERROR(AC6-5,"NA") -> 45651 | AE6: =IFERROR(AD6-7,"NA") -> 45644 | AF6: =CEILING((AC6-TODAY())/7,1) -> -65 | AG6: =CEILING((AD6-TODAY())/7,1) -> -66 | AH6: =CEILING((AE6-TODAY())/7,1) -> -67 | AI6: =COUNTIFS('Profiles Tracker'!E:E,#REF!,'Profiles Tracker'!G:G,Q$1,'Profiles Tracker'!#REF!,"Week 14") -> #REF! | AJ6: =COUNTIFS('Profiles Tracker'!E:E,#REF!,'Profiles Tracker'!G:G,Q$1,'Profiles Tracker'!#REF!,"Week 15") -> #REF! | AK6: =COUNTIFS('Profiles Tracker'!E:E,#REF!,'Profiles Tracker'!G:G,Q$1,'Profiles Tracker'!#REF!,"Week 16") -> #REF! | AL6: =COUNTIFS('Profiles Tracker'!E:E,#REF!,'Profiles Tracker'!G:G,Q$1,'Profiles Tracker'!#REF!,"Week 17") -> #REF! | AM6: =COUNTIFS('Profiles Tracker'!E:E,#REF!,'Profiles Tracker'!G:G,Q$1,'Profiles Tracker'!#REF!,"Week 18") -> #REF!
A7: =ROW()-1 -> 6 | B7: ADCL | C7: Earthwork | E7: 45668 | F7: DPM Earthwork | G7: 1 | H7: 45716 | I7: Mr. Raghu Rama Raju | J7: Mr. Ravindra Varma | K7: - | L7: ADCL-06 | M7: APM & Above
A8: =ROW()-1 -> 7 | B8: ADCL | C8: Structures | E8: 45668 | F8: Sr.Engineer (Structures ) | G8: 14 | H8: 45716 | I8: Mr. Radha Krishna (Consultant) | J8: Mr. Ravindra Varma | K8: ANY-05 | L8: ADCL-07 | M8: APM Below | N8: =COUNTIFS('Profiles Tracker'!E:E,#REF!,'Profiles Tracker'!G:G,"Profile shared with Interviewer") -> 0 | O8: =COUNTIFS('Profiles Tracker'!E:E,#REF!,'Profiles Tracker'!G:G,"Shortlisted for next round of interview") -> 0 | P8: =COUNTIFS('Profiles Tracker'!E:E,#REF!,'Profiles Tracker'!G:G,P$1) -> 0 | Q8: =COUNTIFS('Profiles Tracker'!E:E,#REF!,'Profiles Tracker'!G:G,Q$1) -> 0 | R8: =COUNTIFS('Profiles Tracker'!E:E,#REF!,'Profiles Tracker'!G:G,R$1) -> 0 | S8: =COUNTIFS('Profiles Tracker'!E:E,#REF!,'Profiles Tracker'!G:G,"Interview Done",'Profiles Tracker'!O:O,"Rejected") -> 0 | T8: =COUNTIFS('Profiles Tracker'!E:E,#REF!,'Profiles Tracker'!G:G,T$1) -> 0 | U8: =N8+P8+Q8+R8+S8+T8 -> 0 | V8: =IF((G8-R8-Q8)<1,0,G8-R8-Q8) -> 14 | W8: =FLOOR(G8,1) -> 14 | X8: =FLOOR(W8,1) -> 14 | Y8: =X8*3 -> 42 | Z8: =IF(W8-SUM(Q8:R8)<1,0,W8-SUM(Q8:R8)) -> 14 | AA8: =IF(X8-SUM(P8:R8)<1,0,X8-SUM(P8:R8)) -> 14 | AB8: =IF(AA8*3-N8<1,0,AA8*3-N8) -> 42 | AC8: =IF(M8="APM Below",H8-45,IF(M8="APM & Above", H8-60,H8-90)) -> 45671 | AD8: =IFERROR(AC8-5,"NA") -> 45666 | AE8: =IFERROR(AD8-7,"NA") -> 45659 | AF8: =CEILING((AC8-TODAY())/7,1) -> -63 | AG8: =CEILING((AD8-TODAY())/7,1) -> -64 | AH8: =CEILING((AE8-TODAY())/7,1) -> -65 | AI8: =COUNTIFS('Profiles Tracker'!E:E,#REF!,'Profiles Tracker'!G:G,Q$1,'Profiles Tracker'!#REF!,"Week 14") -> #REF! | AJ8: =COUNTIFS('Profiles Tracker'!E:E,#REF!,'Profiles Tracker'!G:G,Q$1,'Profiles Tracker'!#REF!,"Week 15") -> #REF! | AK8: =COUNTIFS('Profiles Tracker'!E:E,#REF!,'Profiles Tracker'!G:G,Q$1,'Profiles Tracker'!#REF!,"Week 16") -> #REF! | AL8: =COUNTIFS('Profiles Tracker'!E:E,#REF!,'Profiles Tracker'!G:G,Q$1,'Profiles Tracker'!#REF!,"Week 17") -> #REF! | AM8: =COUNTIFS('Profiles Tracker'!E:E,#REF!,'Profiles Tracker'!G:G,Q$1,'Profiles Tracker'!#REF!,"Week 18") -> #REF!
A9: =ROW()-1 -> 8 | B9: ADCL | C9: Roads | E9: 45668 | F9: Sr.Engineer ( Roads & Miscellaneous ) | G9: 26 | H9: 45716 | I9: Mr. Varaprasad (Consultant) | J9: Mr. Ravindra Varma | K9: ANY-06 | L9: ADCL-08 | M9: APM Below | N9: =COUNTIFS('Profiles Tracker'!E:E,#REF!,'Profiles Tracker'!G:G,"Profile shared with Interviewer") -> 0 | O9: =COUNTIFS('Profiles Tracker'!E:E,#REF!,'Profiles Tracker'!G:G,"Shortlisted for next round of interview") -> 0 | P9: =COUNTIFS('Profiles Tracker'!E:E,#REF!,'Profiles Tracker'!G:G,P$1) -> 0 | Q9: =COUNTIFS('Profiles Tracker'!E:E,#REF!,'Profiles Tracker'!G:G,Q$1) -> 0 | R9: =COUNTIFS('Profiles Tracker'!E:E,#REF!,'Profiles Tracker'!G:G,R$1) -> 0 | S9: =COUNTIFS('Profiles Tracker'!E:E,#REF!,'Profiles Tracker'!G:G,"Interview Done",'Profiles Tracker'!O:O,"Rejected") -> 0 | T9: =COUNTIFS('Profiles Tracker'!E:E,#REF!,'Profiles Tracker'!G:G,T$1) -> 0 | U9: =N9+P9+Q9+R9+S9+T9 -> 0 | V9: =IF((G9-R9-Q9)<1,0,G9-R9-Q9) -> 26 | W9: =FLOOR(G9,1) -> 26 | X9: =FLOOR(W9,1) -> 26 | Y9: =X9*3 -> 78 | Z9: =IF(W9-SUM(Q9:R9)<1,0,W9-SUM(Q9:R9)) -> 26 | AA9: =IF(X9-SUM(P9:R9)<1,0,X9-SUM(P9:R9)) -> 26 | AB9: =IF(AA9*3-N9<1,0,AA9*3-N9) -> 78 | AC9: =IF(M9="APM Below",H9-45,IF(M9="APM & Above", H9-60,H9-90)) -> 45671 | AD9: =IFERROR(AC9-5,"NA") -> 45666 | AE9: =IFERROR(AD9-7,"NA") -> 45659 | AF9: =CEILING((AC9-TODAY())/7,1) -> -63 | AG9: =CEILING((AD9-TODAY())/7,1) -> -64 | AH9: =CEILING((AE9-TODAY())/7,1) -> -65 | AI9: =COUNTIFS('Profiles Tracker'!E:E,#REF!,'Profiles Tracker'!G:G,Q$1,'Profiles Tracker'!#REF!,"Week 14") -> #REF! | AJ9: =COUNTIFS('Profiles Tracker'!E:E,#REF!,'Profiles Tracker'!G:G,Q$1,'Profiles Tracker'!#REF!,"Week 15") -> #REF! | AK9: =COUNTIFS('Profiles Tracker'!E:E,#REF!,'Profiles Tracker'!G:G,Q$1,'Profiles Tracker'!#REF!,"Week 16") -> #REF! | AL9: =COUNTIFS('Profiles Tracker'!E:E,#REF!,'Profiles Tracker'!G:G,Q$1,'Profiles Tracker'!#REF!,"Week 17") -> #REF! | AM9: =COUNTIFS('Profiles Tracker'!E:E,#REF!,'Profiles Tracker'!G:G,Q$1,'Profiles Tracker'!#REF!,"Week 18") -> #REF!
A10: =ROW()-1 -> 9 | B10: ADCL | C10: Structures | E10: 45668 | F10: Engineers ( Structures ) | G10: 18 | H10: 45716 | I10: Mr. Radha Krishna (Consultant) | J10: Mr. Ravindra Varma | K10: ANY-07 | L10: ADCL-09 | M10: APM Below | N10: =COUNTIFS('Profiles Tracker'!E:E,#REF!,'Profiles Tracker'!G:G,"Profile shared with Interviewer") -> 0 | O10: =COUNTIFS('Profiles Tracker'!E:E,#REF!,'Profiles Tracker'!G:G,"Shortlisted for next round of interview") -> 0 | P10: =COUNTIFS('Profiles Tracker'!E:E,#REF!,'Profiles Tracker'!G:G,P$1) -> 0 | Q10: =COUNTIFS('Profiles Tracker'!E:E,#REF!,'Profiles Tracker'!G:G,Q$1) -> 0 | R10: =COUNTIFS('Profiles Tracker'!E:E,#REF!,'Profiles Tracker'!G:G,R$1) -> 0 | S10: =COUNTIFS('Profiles Tracker'!E:E,#REF!,'Profiles Tracker'!G:G,"Interview Done",'Profiles Tracker'!O:O,"Rejected") -> 0 | T10: =COUNTIFS('Profiles Tracker'!E:E,#REF!,'Profiles Tracker'!G:G,T$1) -> 0 | U10: =N10+P10+Q10+R10+S10+T10 -> 0 | V10: =IF((G10-R10-Q10)<1,0,G10-R10-Q10) -> 18 | W10: =FLOOR(G10,1) -> 18 | X10: =FLOOR(W10,1) -> 18 | Y10: =X10*3 -> 54 | Z10: =IF(W10-SUM(Q10:R10)<1,0,W10-SUM(Q10:R10)) -> 18 | AA10: =IF(X10-SUM(P10:R10)<1,0,X10-SUM(P10:R10)) -> 18 | AB10: =IF(AA10*3-N10<1,0,AA10*3-N10) -> 54 | AC10: =IF(M10="APM Below",H10-45,IF(M10="APM & Above", H10-60,H10-90)) -> 45671 | AD10: =IFERROR(AC10-5,"NA") -> 45666 | AE10: =IFERROR(AD10-7,"NA") -> 45659 | AF10: =CEILING((AC10-TODAY())/7,1) -> -63 | AG10: =CEILING((AD10-TODAY())/7,1) -> -64 | AH10: =CEILING((AE10-TODAY())/7,1) -> -65 | AI10: =COUNTIFS('Profiles Tracker'!E:E,#REF!,'Profiles Tracker'!G:G,Q$1,'Profiles Tracker'!#REF!,"Week 14") -> #REF! | AJ10: =COUNTIFS('Profiles Tracker'!E:E,#REF!,'Profiles Tracker'!G:G,Q$1,'Profiles Tracker'!#REF!,"Week 15") -> #REF! | AK10: =COUNTIFS('Profiles Tracker'!E:E,#REF!,'Profiles Tracker'!G:G,Q$1,'Profiles Tracker'!#REF!,"Week 16") -> #REF! | AL10: =COUNTIFS('Profiles Tracker'!E:E,#REF!,'Profiles Tracker'!G:G,Q$1,'Profiles Tracker'!#REF!,"Week 17") -> #REF! | AM10: =COUNTIFS('Profiles Tracker'!E:E,#REF!,'Profiles Tracker'!G:G,Q$1,'Profiles Tracker'!#REF!,"Week 18") -> #REF!
A11: =ROW()-1 -> 10 | B11: ADCL | C11: Roads | E11: 45668 | F11: Engineers ( Roads ) | G11: 18 | H11: 45716 | I11: Mr. Madhusudhan Reddy | J11: Mr. Ravindra Varma | K11: ANY-08 | L11: ADCL-10 | M11: APM Below | N11: =COUNTIFS('Profiles Tracker'!E:E,#REF!,'Profiles Tracker'!G:G,"Profile shared with Interviewer") -> 0 | O11: =COUNTIFS('Profiles Tracker'!E:E,#REF!,'Profiles Tracker'!G:G,"Shortlisted for next round of interview") -> 0 | P11: =COUNTIFS('Profiles Tracker'!E:E,#REF!,'Profiles Tracker'!G:G,P$1) -> 0 | Q11: =COUNTIFS('Profiles Tracker'!E:E,#REF!,'Profiles Tracker'!G:G,Q$1) -> 0 | R11: =COUNTIFS('Profiles Tracker'!E:E,#REF!,'Profiles Tracker'!G:G,R$1) -> 0 | S11: =COUNTIFS('Profiles Tracker'!E:E,#REF!,'Profiles Tracker'!G:G,"Interview Done",'Profiles Tracker'!O:O,"Rejected") -> 0 | T11: =COUNTIFS('Profiles Tracker'!E:E,#REF!,'Profiles Tracker'!G:G,T$1) -> 0 | U11: =N11+P11+Q11+R11+S11+T11 -> 0 | V11: =IF((G11-R11-Q11)<1,0,G11-R11-Q11) -> 18 | W11: =FLOOR(G11,1) -> 18 | X11: =FLOOR(W11,1) -> 18 | Y11: =X11*3 -> 54 | Z11: =IF(W11-SUM(Q11:R11)<1,0,W11-SUM(Q11:R11)) -> 18 | AA11: =IF(X11-SUM(P11:R11)<1,0,X11-SUM(P11:R11)) -> 18 | AB11: =IF(AA11*3-N11<1,0,AA11*3-N11) -> 54 | AC11: =IF(M11="APM Below",H11-45,IF(M11="APM & Above", H11-60,H11-90)) -> 45671 | AD11: =IFERROR(AC11-5,"NA") -> 45666 | AE11: =IFERROR(AD11-7,"NA") -> 45659 | AF11: =CEILING((AC11-TODAY())/7,1) -> -63 | AG11: =CEILING((AD11-TODAY())/7,1) -> -64 | AH11: =CEILING((AE11-TODAY())/7,1) -> -65 | AI11: =COUNTIFS('Profiles Tracker'!E:E,#REF!,'Profiles Tracker'!G:G,Q$1,'Profiles Tracker'!#REF!,"Week 14") -> #REF! | AJ11: =COUNTIFS('Profiles Tracker'!E:E,#REF!,'Profiles Tracker'!G:G,Q$1,'Profiles Tracker'!#REF!,"Week 15") -> #REF! | AK11: =COUNTIFS('Profiles Tracker'!E:E,#REF!,'Profiles Tracker'!G:G,Q$1,'Profiles Tracker'!#REF!,"Week 16") -> #REF! | AL11: =COUNTIFS('Profiles Tracker'!E:E,#REF!,'Profiles Tracker'!G:G,Q$1,'Profiles Tracker'!#REF!,"Week 17") -> #REF! | AM11: =COUNTIFS('Profiles Tracker'!E:E,#REF!,'Profiles Tracker'!G:G,Q$1,'Profiles Tracker'!#REF!,"Week 18") -> #REF!
A12: =ROW()-1 -> 11 | B12: ADCL | C12: Structures | E12: 45668 | F12: Jr.Engineer ( structures) | G12: 14 | H12: 45716 | I12: Mr. Radha Krishna (Consultant) | J12: Mr. Ravindra Varma | K12: ANY-09 | L12: ADCL-11 | M12: APM Below | N12: =COUNTIFS('Profiles Tracker'!E:E,#REF!,'Profiles Tracker'!G:G,"Profile shared with Interviewer") -> 0 | O12: =COUNTIFS('Profiles Tracker'!E:E,#REF!,'Profiles Tracker'!G:G,"Shortlisted for next round of interview") -> 0 | P12: =COUNTIFS('Profiles Tracker'!E:E,#REF!,'Profiles Tracker'!G:G,P$1) -> 0 | Q12: =COUNTIFS('Profiles Tracker'!E:E,#REF!,'Profiles Tracker'!G:G,Q$1) -> 0 | R12: =COUNTIFS('Profiles Tracker'!E:E,#REF!,'Profiles Tracker'!G:G,R$1) -> 0 | S12: =COUNTIFS('Profiles Tracker'!E:E,#REF!,'Profiles Tracker'!G:G,"Interview Done",'Profiles Tracker'!O:O,"Rejected") -> 0 | T12: =COUNTIFS('Profiles Tracker'!E:E,#REF!,'Profiles Tracker'!G:G,T$1) -> 0 | U12: =N12+P12+Q12+R12+S12+T12 -> 0 | V12: =IF((G12-R12-Q12)<1,0,G12-R12-Q12) -> 14 | W12: =FLOOR(G12,1) -> 14 | X12: =FLOOR(W12,1) -> 14 | Y12: =X12*3 -> 42 | Z12: =IF(W12-SUM(Q12:R12)<1,0,W12-SUM(Q12:R12)) -> 14 | AA12: =IF(X12-SUM(P12:R12)<1,0,X12-SUM(P12:R12)) -> 14 | AB12: =IF(AA12*3-N12<1,0,AA12*3-N12) -> 42 | AC12: =IF(M12="APM Below",H12-45,IF(M12="APM & Above", H12-60,H12-90)) -> 45671 | AD12: =IFERROR(AC12-5,"NA") -> 45666 | AE12: =IFERROR(AD12-7,"NA") -> 45659 | AF12: =CEILING((AC12-TODAY())/7,1) -> -63 | AG12: =CEILING((AD12-TODAY())/7,1) -> -64 | AH12: =CEILING((AE12-TODAY())/7,1) -> -65 | AI12: =COUNTIFS('Profiles Tracker'!E:E,#REF!,'Profiles Tracker'!G:G,Q$1,'Profiles Tracker'!#REF!,"Week 14") -> #REF! | AJ12: =COUNTIFS('Profiles Tracker'!E:E,#REF!,'Profiles Tracker'!G:G,Q$1,'Profiles Tracker'!#REF!,"Week 15") -> #REF! | AK12: =COUNTIFS('Profiles Tracker'!E:E,#REF!,'Profiles Tracker'!G:G,Q$1,'Profiles Tracker'!#REF!,"Week 16") -> #REF! | AL12: =COUNTIFS('Profiles Tracker'!E:E,#REF!,'Profiles Tracker'!G:G,Q$1,'Profiles Tracker'!#REF!,"Week 17") -> #REF! | AM12: =COUNTIFS('Profiles Tracker'!E:E,#REF!,'Profiles Tracker'!G:G,Q$1,'Profiles Tracker'!#REF!,"Week 18") -> #REF!
A13: =ROW()-1 -> 12 | B13: ADCL | C13: Roads | E13: 45668 | F13: Jr. Engineer ( Roads ) | G13: 14 | H13: 45716 | I13: Mr. Madhusudhan Reddy | J13: Mr. Ravindra Varma | K13: ANY-10 | L13: ADCL-12 | M13: APM Below | N13: =COUNTIFS('Profiles Tracker'!E:E,#REF!,'Profiles Tracker'!G:G,"Profile shared with Interviewer") -> 0 | O13: =COUNTIFS('Profiles Tracker'!E:E,#REF!,'Profiles Tracker'!G:G,"Shortlisted for next round of interview") -> 0 | P13: =COUNTIFS('Profiles Tracker'!E:E,#REF!,'Profiles Tracker'!G:G,P$1) -> 0 | Q13: =COUNTIFS('Profiles Tracker'!E:E,#REF!,'Profiles Tracker'!G:G,Q$1) -> 0 | R13: =COUNTIFS('Profiles Tracker'!E:E,#REF!,'Profiles Tracker'!G:G,R$1) -> 0 | S13: =COUNTIFS('Profiles Tracker'!E:E,#REF!,'Profiles Tracker'!G:G,"Interview Done",'Profiles Tracker'!O:O,"Rejected") -> 0 | T13: =COUNTIFS('Profiles Tracker'!E:E,#REF!,'Profiles Tracker'!G:G,T$1) -> 0 | U13: =N13+P13+Q13+R13+S13+T13 -> 0 | V13: =IF((G13-R13-Q13)<1,0,G13-R13-Q13) -> 14 | W13: =FLOOR(G13,1) -> 14 | X13: =FLOOR(W13,1) -> 14 | Y13: =X13*3 -> 42 | Z13: =IF(W13-SUM(Q13:R13)<1,0,W13-SUM(Q13:R13)) -> 14 | AA13: =IF(X13-SUM(P13:R13)<1,0,X13-SUM(P13:R13)) -> 14 | AB13: =IF(AA13*3-N13<1,0,AA13*3-N13) -> 42 | AC13: =IF(M13="APM Below",H13-45,IF(M13="APM & Above", H13-60,H13-90)) -> 45671 | AD13: =IFERROR(AC13-5,"NA") -> 45666 | AE13: =IFERROR(AD13-7,"NA") -> 45659 | AF13: =CEILING((AC13-TODAY())/7,1) -> -63 | AG13: =CEILING((AD13-TODAY())/7,1) -> -64 | AH13: =CEILING((AE13-TODAY())/7,1) -> -65 | AI13: =COUNTIFS('Profiles Tracker'!E:E,#REF!,'Profiles Tracker'!G:G,Q$1,'Profiles Tracker'!#REF!,"Week 14") -> #REF! | AJ13: =COUNTIFS('Profiles Tracker'!E:E,#REF!,'Profiles Tracker'!G:G,Q$1,'Profiles Tracker'!#REF!,"Week 15") -> #REF! | AK13: =COUNTIFS('Profiles Tracker'!E:E,#REF!,'Profiles Tracker'!G:G,Q$1,'Profiles Tracker'!#REF!,"Week 16") -> #REF! | AL13: =COUNTIFS('Profiles Tracker'!E:E,#REF!,'Profiles Tracker'!G:G,Q$1,'Profiles Tracker'!#REF!,"Week 17") -> #REF! | AM13: =COUNTIFS('Profiles Tracker'!E:E,#REF!,'Profiles Tracker'!G:G,Q$1,'Profiles Tracker'!#REF!,"Week 18") -> #REF!
A14: =ROW()-1 -> 13 | B14: ADCL | E14: 45668 | F14: Surveyors | G14: 28 | H14: 45716 | I14: Mr. Swaroop (Consultant) | J14: Mr. Srinivas | K14: ANY-11 | L14: ADCL-13 | M14: APM Below | N14: =COUNTIFS('Profiles Tracker'!E:E,#REF!,'Profiles Tracker'!G:G,"Profile shared with Interviewer") -> 0 | O14: =COUNTIFS('Profiles Tracker'!E:E,#REF!,'Profiles Tracker'!G:G,"Shortlisted for next round of interview") -> 0 | P14: =COUNTIFS('Profiles Tracker'!E:E,#REF!,'Profiles Tracker'!G:G,P$1) -> 0 | Q14: =COUNTIFS('Profiles Tracker'!E:E,#REF!,'Profiles Tracker'!G:G,Q$1) -> 0 | R14: =COUNTIFS('Profiles Tracker'!E:E,#REF!,'Profiles Tracker'!G:G,R$1) -> 0 | S14: =COUNTIFS('Profiles Tracker'!E:E,#REF!,'Profiles Tracker'!G:G,"Interview Done",'Profiles Tracker'!O:O,"Rejected") -> 0 | T14: =COUNTIFS('Profiles Tracker'!E:E,#REF!,'Profiles Tracker'!G:G,T$1) -> 0 | U14: =N14+P14+Q14+R14+S14+T14 -> 0 | V14: =IF((G14-R14-Q14)<1,0,G14-R14-Q14) -> 28 | W14: =FLOOR(G14,1) -> 28 | X14: =FLOOR(W14,1) -> 28 | Y14: =X14*3 -> 84 | Z14: =IF(W14-SUM(Q14:R14)<1,0,W14-SUM(Q14:R14)) -> 28 | AA14: =IF(X14-SUM(P14:R14)<1,0,X14-SUM(P14:R14)) -> 28 | AB14: =IF(AA14*3-N14<1,0,AA14*3-N14) -> 84 | AC14: =IF(M14="APM Below",H14-45,IF(M14="APM & Above", H14-60,H14-90)) -> 45671 | AD14: =IFERROR(AC14-5,"NA") -> 45666 | AE14: =IFERROR(AD14-7,"NA") -> 45659 | AF14: =CEILING((AC14-TODAY())/7,1) -> -63 | AG14: =CEILING((AD14-TODAY())/7,1) -> -64 | AH14: =CEILING((AE14-TODAY())/7,1) -> -65 | AI14: =COUNTIFS('Profiles Tracker'!E:E,#REF!,'Profiles Tracker'!G:G,Q$1,'Profiles Tracker'!#REF!,"Week 14") -> #REF! | AJ14: =COUNTIFS('Profiles Tracker'!E:E,#REF!,'Profiles Tracker'!G:G,Q$1,'Profiles Tracker'!#REF!,"Week 15") -> #REF! | AK14: =COUNTIFS('Profiles Tracker'!E:E,#REF!,'Profiles Tracker'!G:G,Q$1,'Profiles Tracker'!#REF!,"Week 16") -> #REF! | AL14: =COUNTIFS('Profiles Tracker'!E:E,#REF!,'Profiles Tracker'!G:G,Q$1,'Profiles Tracker'!#REF!,"Week 17") -> #REF! | AM14: =COUNTIFS('Profiles Tracker'!E:E,#REF!,'Profiles Tracker'!G:G,Q$1,'Profiles Tracker'!#REF!,"Week 18") -> #REF!
A15: =ROW()-1 -> 14 | B15: ADCL | C15: Safety | E15: 45668 | F15: Safety Executives | G15: 14 | H15: 45747 | I15: Mr. Palem Krishna Reddy | J15: Mr. Venu | K15: ANY-49 | L15: ADCL-14 | M15: APM Below | N15: =COUNTIFS('Profiles Tracker'!E:E,#REF!,'Profiles Tracker'!G:G,"Profile shared with Interviewer") -> 0 | O15: =COUNTIFS('Profiles Tracker'!E:E,#REF!,'Profiles Tracker'!G:G,"Shortlisted for next round of interview") -> 0 | P15: =COUNTIFS('Profiles Tracker'!E:E,#REF!,'Profiles Tracker'!G:G,P$1) -> 0 | Q15: =COUNTIFS('Profiles Tracker'!E:E,#REF!,'Profiles Tracker'!G:G,Q$1) -> 0 | R15: =COUNTIFS('Profiles Tracker'!E:E,#REF!,'Profiles Tracker'!G:G,R$1) -> 0 | S15: =COUNTIFS('Profiles Tracker'!E:E,#REF!,'Profiles Tracker'!G:G,"Interview Done",'Profiles Tracker'!O:O,"Rejected") -> 0 | T15: =COUNTIFS('Profiles Tracker'!E:E,#REF!,'Profiles Tracker'!G:G,T$1) -> 0 | U15: =N15+P15+Q15+R15+S15+T15 -> 0 | V15: =IF((G15-R15-Q15)<1,0,G15-R15-Q15) -> 14 | W15: =FLOOR(G15,1) -> 14 | X15: =FLOOR(W15,1) -> 14 | Y15: =X15*3 -> 42 | Z15: =IF(W15-SUM(Q15:R15)<1,0,W15-SUM(Q15:R15)) -> 14 | AA15: =IF(X15-SUM(P15:R15)<1,0,X15-SUM(P15:R15)) -> 14 | AB15: =IF(AA15*3-N15<1,0,AA15*3-N15) -> 42 | AC15: =IF(M15="APM Below",H15-45,IF(M15="APM & Above", H15-60,H15-90)) -> 45702 | AD15: =IFERROR(AC15-5,"NA") -> 45697 | AE15: =IFERROR(AD15-7,"NA") -> 45690 | AF15: =CEILING((AC15-TODAY())/7,1) -> -59 | AG15: =CEILING((AD15-TODAY())/7,1) -> -59 | AH15: =CEILING((AE15-TODAY())/7,1) -> -60 | AI15: =COUNTIFS('Profiles Tracker'!E:E,#REF!,'Profiles Tracker'!G:G,Q$1,'Profiles Tracker'!#REF!,"Week 14") -> #REF! | AJ15: =COUNTIFS('Profiles Tracker'!E:E,#REF!,'Profiles Tracker'!G:G,Q$1,'Profiles Tracker'!#REF!,"Week 15") -> #REF! | AK15: =COUNTIFS('Profiles Tracker'!E:E,#REF!,'Profiles Tracker'!G:G,Q$1,'Profiles Tracker'!#REF!,"Week 16") -> #REF! | AL15: =COUNTIFS('Profiles Tracker'!E:E,#REF!,'Profiles Tracker'!G:G,Q$1,'Profiles Tracker'!#REF!,"Week 17") -> #REF! | AM15: =COUNTIFS('Profiles Tracker'!E:E,#REF!,'Profiles Tracker'!G:G,Q$1,'Profiles Tracker'!#REF!,"Week 18") -> #REF!
A16: =ROW()-1 -> 15 | B16: ADCL | C16: Safety | E16: 45668 | F16: Safety Officers | G16: 14 | H16: 45716 | I16: Mr. Palem Krishna Reddy | J16: Mr. Venu | K16: ANY-13 | L16: ADCL-15 | M16: APM Below | N16: =COUNTIFS('Profiles Tracker'!E:E,#REF!,'Profiles Tracker'!G:G,"Profile shared with Interviewer") -> 0 | O16: =COUNTIFS('Profiles Tracker'!E:E,#REF!,'Profiles Tracker'!G:G,"Shortlisted for next round of interview") -> 0 | P16: =COUNTIFS('Profiles Tracker'!E:E,#REF!,'Profiles Tracker'!G:G,P$1) -> 0 | Q16: =COUNTIFS('Profiles Tracker'!E:E,#REF!,'Profiles Tracker'!G:G,Q$1) -> 0 | R16: =COUNTIFS('Profiles Tracker'!E:E,#REF!,'Profiles Tracker'!G:G,R$1) -> 0 | S16: =COUNTIFS('Profiles Tracker'!E:E,#REF!,'Profiles Tracker'!G:G,"Interview Done",'Profiles Tracker'!O:O,"Rejected") -> 0 | T16: =COUNTIFS('Profiles Tracker'!E:E,#REF!,'Profiles Tracker'!G:G,T$1) -> 0 | U16: =N16+P16+Q16+R16+S16+T16 -> 0 | V16: =IF((G16-R16-Q16)<1,0,G16-R16-Q16) -> 14 | W16: =FLOOR(G16,1) -> 14 | X16: =FLOOR(W16,1) -> 14 | Y16: =X16*3 -> 42 | Z16: =IF(W16-SUM(Q16:R16)<1,0,W16-SUM(Q16:R16)) -> 14 | AA16: =IF(X16-SUM(P16:R16)<1,0,X16-SUM(P16:R16)) -> 14 | AB16: =IF(AA16*3-N16<1,0,AA16*3-N16) -> 42 | AC16: =IF(M16="APM Below",H16-45,IF(M16="APM & Above", H16-60,H16-90)) -> 45671 | AD16: =IFERROR(AC16-5,"NA") -> 45666 | AE16: =IFERROR(AD16-7,"NA") -> 45659 | AF16: =CEILING((AC16-TODAY())/7,1) -> -63 | AG16: =CEILING((AD16-TODAY())/7,1) -> -64 | AH16: =CEILING((AE16-TODAY())/7,1) -> -65 | AI16: =COUNTIFS('Profiles Tracker'!E:E,#REF!,'Profiles Tracker'!G:G,Q$1,'Profiles Tracker'!#REF!,"Week 14") -> #REF! | AJ16: =COUNTIFS('Profiles Tracker'!E:E,#REF!,'Profiles Tracker'!G:G,Q$1,'Profiles Tracker'!#REF!,"Week 15") -> #REF! | AK16: =COUNTIFS('Profiles Tracker'!E:E,#REF!,'Profiles Tracker'!G:G,Q$1,'Profiles Tracker'!#REF!,"Week 16") -> #REF! | AL16: =COUNTIFS('Profiles Tracker'!E:E,#REF!,'Profiles Tracker'!G:G,Q$1,'Profiles Tracker'!#REF!,"Week 17") -> #REF! | AM16: =COUNTIFS('Profiles Tracker'!E:E,#REF!,'Profiles Tracker'!G:G,Q$1,'Profiles Tracker'!#REF!,"Week 18") -> #REF!
A17: =ROW()-1 -> 16 | B17: ADCL | C17: QC | E17: 45668 | F17: Manager/Asst Manager ( QC ) | G17: 5 | H17: 45716 | I17: Mr. Rudra Murthy G | J17: Mr. Ravindra Varma | K17: ANY-14 | L17: ADCL-16 | M17: APM & Above | N17: =COUNTIFS('Profiles Tracker'!E:E,#REF!,'Profiles Tracker'!G:G,"Profile shared with Interviewer") -> 0 | O17: =COUNTIFS('Profiles Tracker'!E:E,#REF!,'Profiles Tracker'!G:G,"Shortlisted for next round of interview") -> 0 | P17: =COUNTIFS('Profiles Tracker'!E:E,#REF!,'Profiles Tracker'!G:G,P$1) -> 0 | Q17: =COUNTIFS('Profiles Tracker'!E:E,#REF!,'Profiles Tracker'!G:G,Q$1) -> 0 | R17: =COUNTIFS('Profiles Tracker'!E:E,#REF!,'Profiles Tracker'!G:G,R$1) -> 0 | S17: =COUNTIFS('Profiles Tracker'!E:E,#REF!,'Profiles Tracker'!G:G,"Interview Done",'Profiles Tracker'!O:O,"Rejected") -> 0 | T17: =COUNTIFS('Profiles Tracker'!E:E,#REF!,'Profiles Tracker'!G:G,T$1) -> 0 | U17: =N17+P17+Q17+R17+S17+T17 -> 0 | V17: =IF((G17-R17-Q17)<1,0,G17-R17-Q17) -> 5 | W17: =FLOOR(G17,1) -> 5 | X17: =FLOOR(W17,1) -> 5 | Y17: =X17*3 -> 15 | Z17: =IF(W17-SUM(Q17:R17)<1,0,W17-SUM(Q17:R17)) -> 5 | AA17: =IF(X17-SUM(P17:R17)<1,0,X17-SUM(P17:R17)) -> 5 | AB17: =IF(AA17*3-N17<1,0,AA17*3-N17) -> 15 | AC17: =IF(M17="APM Below",H17-45,IF(M17="APM & Above", H17-60,H17-90)) -> 45656 | AD17: =IFERROR(AC17-5,"NA") -> 45651 | AE17: =IFERROR(AD17-7,"NA") -> 45644 | AF17: =CEILING((AC17-TODAY())/7,1) -> -65 | AG17: =CEILING((AD17-TODAY())/7,1) -> -66 | AH17: =CEILING((AE17-TODAY())/7,1) -> -67 | AI17: =COUNTIFS('Profiles Tracker'!E:E,#REF!,'Profiles Tracker'!G:G,Q$1,'Profiles Tracker'!#REF!,"Week 14") -> #REF! | AJ17: =COUNTIFS('Profiles Tracker'!E:E,#REF!,'Profiles Tracker'!G:G,Q$1,'Profiles Tracker'!#REF!,"Week 15") -> #REF! | AK17: =COUNTIFS('Profiles Tracker'!E:E,#REF!,'Profiles Tracker'!G:G,Q$1,'Profiles Tracker'!#REF!,"Week 16") -> #REF! | AL17: =COUNTIFS('Profiles Tracker'!E:E,#REF!,'Profiles Tracker'!G:G,Q$1,'Profiles Tracker'!#REF!,"Week 17") -> #REF! | AM17: =COUNTIFS('Profiles Tracker'!E:E,#REF!,'Profiles Tracker'!G:G,Q$1,'Profiles Tracker'!#REF!,"Week 18") -> #REF!
A18: =ROW()-1 -> 17 | B18: ADCL | C18: QC | E18: 45668 | F18: Sr.Engineer (QC) | G18: 10 | H18: 45716 | I18: Mr. Rudra Murthy G | J18: Mr. Ravindra Varma | K18: ANY-15 | L18: ADCL-17 | M18: APM Below | N18: =COUNTIFS('Profiles Tracker'!E:E,#REF!,'Profiles Tracker'!G:G,"Profile shared with Interviewer") -> 0 | O18: =COUNTIFS('Profiles Tracker'!E:E,#REF!,'Profiles Tracker'!G:G,"Shortlisted for next round of interview") -> 0 | P18: =COUNTIFS('Profiles Tracker'!E:E,#REF!,'Profiles Tracker'!G:G,P$1) -> 0 | Q18: =COUNTIFS('Profiles Tracker'!E:E,#REF!,'Profiles Tracker'!G:G,Q$1) -> 0 | R18: =COUNTIFS('Profiles Tracker'!E:E,#REF!,'Profiles Tracker'!G:G,R$1) -> 0 | S18: =COUNTIFS('Profiles Tracker'!E:E,#REF!,'Profiles Tracker'!G:G,"Interview Done",'Profiles Tracker'!O:O,"Rejected") -> 0 | T18: =COUNTIFS('Profiles Tracker'!E:E,#REF!,'Profiles Tracker'!G:G,T$1) -> 0 | U18: =N18+P18+Q18+R18+S18+T18 -> 0 | V18: =IF((G18-R18-Q18)<1,0,G18-R18-Q18) -> 10 | W18: =FLOOR(G18,1) -> 10 | X18: =FLOOR(W18,1) -> 10 | Y18: =X18*3 -> 30 | Z18: =IF(W18-SUM(Q18:R18)<1,0,W18-SUM(Q18:R18)) -> 10 | AA18: =IF(X18-SUM(P18:R18)<1,0,X18-SUM(P18:R18)) -> 10 | AB18: =IF(AA18*3-N18<1,0,AA18*3-N18) -> 30 | AC18: =IF(M18="APM Below",H18-45,IF(M18="APM & Above", H18-60,H18-90)) -> 45671 | AD18: =IFERROR(AC18-5,"NA") -> 45666 | AE18: =IFERROR(AD18-7,"NA") -> 45659 | AF18: =CEILING((AC18-TODAY())/7,1) -> -63 | AG18: =CEILING((AD18-TODAY())/7,1) -> -64 | AH18: =CEILING((AE18-TODAY())/7,1) -> -65 | AI18: =COUNTIFS('Profiles Tracker'!E:E,#REF!,'Profiles Tracker'!G:G,Q$1,'Profiles Tracker'!#REF!,"Week 14") -> #REF! | AJ18: =COUNTIFS('Profiles Tracker'!E:E,#REF!,'Profiles Tracker'!G:G,Q$1,'Profiles Tracker'!#REF!,"Week 15") -> #REF! | AK18: =COUNTIFS('Profiles Tracker'!E:E,#REF!,'Profiles Tracker'!G:G,Q$1,'Profiles Tracker'!#REF!,"Week 16") -> #REF! | AL18: =COUNTIFS('Profiles Tracker'!E:E,#REF!,'Profiles Tracker'!G:G,Q$1,'Profiles Tracker'!#REF!,"Week 17") -> #REF! | AM18: =COUNTIFS('Profiles Tracker'!E:E,#REF!,'Profiles Tracker'!G:G,Q$1,'Profiles Tracker'!#REF!,"Week 18") -> #REF!
A19: =ROW()-1 -> 18 | B19: ADCL | C19: QC | E19: 45668 | F19: Engineer/Asst Engineer - QC | G19: 23 | H19: 45716 | I19: Mr. Rudra Murthy G | J19: Mr. Ravindra Varma | K19: ANY-16 | L19: ADCL-18 | M19: APM Below | N19: =COUNTIFS('Profiles Tracker'!E:E,#REF!,'Profiles Tracker'!G:G,"Profile shared with Interviewer") -> 0 | O19: =COUNTIFS('Profiles Tracker'!E:E,#REF!,'Profiles Tracker'!G:G,"Shortlisted for next round of interview") -> 0 | P19: =COUNTIFS('Profiles Tracker'!E:E,#REF!,'Profiles Tracker'!G:G,P$1) -> 0 | Q19: =COUNTIFS('Profiles Tracker'!E:E,#REF!,'Profiles Tracker'!G:G,Q$1) -> 0 | R19: =COUNTIFS('Profiles Tracker'!E:E,#REF!,'Profiles Tracker'!G:G,R$1) -> 0 | S19: =COUNTIFS('Profiles Tracker'!E:E,#REF!,'Profiles Tracker'!G:G,"Interview Done",'Profiles Tracker'!O:O,"Rejected") -> 0 | T19: =COUNTIFS('Profiles Tracker'!E:E,#REF!,'Profiles Tracker'!G:G,T$1) -> 0 | U19: =N19+P19+Q19+R19+S19+T19 -> 0 | V19: =IF((G19-R19-Q19)<1,0,G19-R19-Q19) -> 23 | W19: =FLOOR(G19,1) -> 23 | X19: =FLOOR(W19,1) -> 23 | Y19: =X19*3 -> 69 | Z19: =IF(W19-SUM(Q19:R19)<1,0,W19-SUM(Q19:R19)) -> 23 | AA19: =IF(X19-SUM(P19:R19)<1,0,X19-SUM(P19:R19)) -> 23 | AB19: =IF(AA19*3-N19<1,0,AA19*3-N19) -> 69 | AC19: =IF(M19="APM Below",H19-45,IF(M19="APM & Above", H19-60,H19-90)) -> 45671 | AD19: =IFERROR(AC19-5,"NA") -> 45666 | AE19: =IFERROR(AD19-7,"NA") -> 45659 | AF19: =CEILING((AC19-TODAY())/7,1) -> -63 | AG19: =CEILING((AD19-TODAY())/7,1) -> -64 | AH19: =CEILING((AE19-TODAY())/7,1) -> -65 | AI19: =COUNTIFS('Profiles Tracker'!E:E,#REF!,'Profiles Tracker'!G:G,Q$1,'Profiles Tracker'!#REF!,"Week 14") -> #REF! | AJ19: =COUNTIFS('Profiles Tracker'!E:E,#REF!,'Profiles Tracker'!G:G,Q$1,'Profiles Tracker'!#REF!,"Week 15") -> #REF! | AK19: =COUNTIFS('Profiles Tracker'!E:E,#REF!,'Profiles Tracker'!G:G,Q$1,'Profiles Tracker'!#REF!,"Week 16") -> #REF! | AL19: =COUNTIFS('Profiles Tracker'!E:E,#REF!,'Profiles Tracker'!G:G,Q$1,'Profiles Tracker'!#REF!,"Week 17") -> #REF! | AM19: =COUNTIFS('Profiles Tracker'!E:E,#REF!,'Profiles Tracker'!G:G,Q$1,'Profiles Tracker'!#REF!,"Week 18") -> #REF!
A20: =ROW()-1 -> 19 | B20: ADCL | C20: QC | E20: 45668 | F20: Technicians | G20: 18 | H20: 45716 | I20: Mr. Rudra Murthy G | J20: Mr. Ravindra Varma | K20: ANY-17 | L20: ADCL-19 | M20: APM Below | N20: =COUNTIFS('Profiles Tracker'!E:E,#REF!,'Profiles Tracker'!G:G,"Profile shared with Interviewer") -> 0 | O20: =COUNTIFS('Profiles Tracker'!E:E,#REF!,'Profiles Tracker'!G:G,"Shortlisted for next round of interview") -> 0 | P20: =COUNTIFS('Profiles Tracker'!E:E,#REF!,'Profiles Tracker'!G:G,P$1) -> 0 | Q20: =COUNTIFS('Profiles Tracker'!E:E,#REF!,'Profiles Tracker'!G:G,Q$1) -> 0 | R20: =COUNTIFS('Profiles Tracker'!E:E,#REF!,'Profiles Tracker'!G:G,R$1) -> 0 | S20: =COUNTIFS('Profiles Tracker'!E:E,#REF!,'Profiles Tracker'!G:G,"Interview Done",'Profiles Tracker'!O:O,"Rejected") -> 0 | T20: =COUNTIFS('Profiles Tracker'!E:E,#REF!,'Profiles Tracker'!G:G,T$1) -> 0 | U20: =N20+P20+Q20+R20+S20+T20 -> 0 | V20: =IF((G20-R20-Q20)<1,0,G20-R20-Q20) -> 18 | W20: =FLOOR(G20,1) -> 18 | X20: =FLOOR(W20,1) -> 18 | Y20: =X20*3 -> 54 | Z20: =IF(W20-SUM(Q20:R20)<1,0,W20-SUM(Q20:R20)) -> 18 | AA20: =IF(X20-SUM(P20:R20)<1,0,X20-SUM(P20:R20)) -> 18 | AB20: =IF(AA20*3-N20<1,0,AA20*3-N20) -> 54 | AC20: =IF(M20="APM Below",H20-45,IF(M20="APM & Above", H20-60,H20-90)) -> 45671 | AD20: =IFERROR(AC20-5,"NA") -> 45666 | AE20: =IFERROR(AD20-7,"NA") -> 45659 | AF20: =CEILING((AC20-TODAY())/7,1) -> -63 | AG20: =CEILING((AD20-TODAY())/7,1) -> -64 | AH20: =CEILING((AE20-TODAY())/7,1) -> -65 | AI20: =COUNTIFS('Profiles Tracker'!E:E,#REF!,'Profiles Tracker'!G:G,Q$1,'Profiles Tracker'!#REF!,"Week 14") -> #REF! | AJ20: =COUNTIFS('Profiles Tracker'!E:E,#REF!,'Profiles Tracker'!G:G,Q$1,'Profiles Tracker'!#REF!,"Week 15") -> #REF! | AK20: =COUNTIFS('Profiles Tracker'!E:E,#REF!,'Profiles Tracker'!G:G,Q$1,'Profiles Tracker'!#REF!,"Week 16") -> #REF! | AL20: =COUNTIFS('Profiles Tracker'!E:E,#REF!,'Profiles Tracker'!G:G,Q$1,'Profiles Tracker'!#REF!,"Week 17") -> #REF! | AM20: =COUNTIFS('Profiles Tracker'!E:E,#REF!,'Profiles Tracker'!G:G,Q$1,'Profiles Tracker'!#REF!,"Week 18") -> #REF!
A21: =ROW()-1 -> 20 | B21: ADCL | C21: Planning & QS | E21: 45668 | F21: DGM ( Planning & QS ) | G21: 1 | H21: 45716 | I21: Mr. Subash | J21: Mr. Ravindra Varma | K21: ANY-18 | L21: ADCL-20 | M21: APM & Above | N21: =COUNTIFS('Profiles Tracker'!E:E,#REF!,'Profiles Tracker'!G:G,"Profile shared with Interviewer") -> 0 | O21: =COUNTIFS('Profiles Tracker'!E:E,#REF!,'Profiles Tracker'!G:G,"Shortlisted for next round of interview") -> 0 | P21: =COUNTIFS('Profiles Tracker'!E:E,#REF!,'Profiles Tracker'!G:G,P$1) -> 0 | Q21: =COUNTIFS('Profiles Tracker'!E:E,#REF!,'Profiles Tracker'!G:G,Q$1) -> 0 | R21: =COUNTIFS('Profiles Tracker'!E:E,#REF!,'Profiles Tracker'!G:G,R$1) -> 0 | S21: =COUNTIFS('Profiles Tracker'!E:E,#REF!,'Profiles Tracker'!G:G,"Interview Done",'Profiles Tracker'!O:O,"Rejected") -> 0 | T21: =COUNTIFS('Profiles Tracker'!E:E,#REF!,'Profiles Tracker'!G:G,T$1) -> 0 | U21: =N21+P21+Q21+R21+S21+T21 -> 0 | V21: =IF((G21-R21-Q21)<1,0,G21-R21-Q21) -> 1 | W21: =FLOOR(G21,1) -> 1 | X21: =FLOOR(W21,1) -> 1 | Y21: =X21*3 -> 3 | Z21: =IF(W21-SUM(Q21:R21)<1,0,W21-SUM(Q21:R21)) -> 1 | AA21: =IF(X21-SUM(P21:R21)<1,0,X21-SUM(P21:R21)) -> 1 | AB21: =IF(AA21*3-N21<1,0,AA21*3-N21) -> 3 | AC21: =IF(M21="APM Below",H21-45,IF(M21="APM & Above", H21-60,H21-90)) -> 45656 | AD21: =IFERROR(AC21-5,"NA") -> 45651 | AE21: =IFERROR(AD21-7,"NA") -> 45644 | AF21: =CEILING((AC21-TODAY())/7,1) -> -65 | AG21: =CEILING((AD21-TODAY())/7,1) -> -66 | AH21: =CEILING((AE21-TODAY())/7,1) -> -67 | AI21: =COUNTIFS('Profiles Tracker'!E:E,#REF!,'Profiles Tracker'!G:G,Q$1,'Profiles Tracker'!#REF!,"Week 14") -> #REF! | AJ21: =COUNTIFS('Profiles Tracker'!E:E,#REF!,'Profiles Tracker'!G:G,Q$1,'Profiles Tracker'!#REF!,"Week 15") -> #REF! | AK21: =COUNTIFS('Profiles Tracker'!E:E,#REF!,'Profiles Tracker'!G:G,Q$1,'Profiles Tracker'!#REF!,"Week 16") -> #REF! | AL21: =COUNTIFS('Profiles Tracker'!E:E,#REF!,'Profiles Tracker'!G:G,Q$1,'Profiles Tracker'!#REF!,"Week 17") -> #REF! | AM21: =COUNTIFS('Profiles Tracker'!E:E,#REF!,'Profiles Tracker'!G:G,Q$1,'Profiles Tracker'!#REF!,"Week 18") -> #REF!
A22: =ROW()-1 -> 21 | B22: ADCL | C22: Planning & QS | E22: 45668 | F22: Planning & QS Manager | G22: 8 | H22: 45716 | I22: Mr. Subash | J22: Mr. Ravindra Varma | K22: ANY-19 | L22: ADCL-21 | M22: APM & Above | N22: =COUNTIFS('Profiles Tracker'!E:E,#REF!,'Profiles Tracker'!G:G,"Profile shared with Interviewer") -> 0 | O22: =COUNTIFS('Profiles Tracker'!E:E,#REF!,'Profiles Tracker'!G:G,"Shortlisted for next round of interview") -> 0 | P22: =COUNTIFS('Profiles Tracker'!E:E,#REF!,'Profiles Tracker'!G:G,P$1) -> 0 | Q22: =COUNTIFS('Profiles Tracker'!E:E,#REF!,'Profiles Tracker'!G:G,Q$1) -> 0 | R22: =COUNTIFS('Profiles Tracker'!E:E,#REF!,'Profiles Tracker'!G:G,R$1) -> 0 | S22: =COUNTIFS('Profiles Tracker'!E:E,#REF!,'Profiles Tracker'!G:G,"Interview Done",'Profiles Tracker'!O:O,"Rejected") -> 0 | T22: =COUNTIFS('Profiles Tracker'!E:E,#REF!,'Profiles Tracker'!G:G,T$1) -> 0 | U22: =N22+P22+Q22+R22+S22+T22 -> 0 | V22: =IF((G22-R22-Q22)<1,0,G22-R22-Q22) -> 8 | W22: =FLOOR(G22,1) -> 8 | X22: =FLOOR(W22,1) -> 8 | Y22: =X22*3 -> 24 | Z22: =IF(W22-SUM(Q22:R22)<1,0,W22-SUM(Q22:R22)) -> 8 | AA22: =IF(X22-SUM(P22:R22)<1,0,X22-SUM(P22:R22)) -> 8 | AB22: =IF(AA22*3-N22<1,0,AA22*3-N22) -> 24 | AC22: =IF(M22="APM Below",H22-45,IF(M22="APM & Above", H22-60,H22-90)) -> 45656 | AD22: =IFERROR(AC22-5,"NA") -> 45651 | AE22: =IFERROR(AD22-7,"NA") -> 45644 | AF22: =CEILING((AC22-TODAY())/7,1) -> -65 | AG22: =CEILING((AD22-TODAY())/7,1) -> -66 | AH22: =CEILING((AE22-TODAY())/7,1) -> -67 | AI22: =COUNTIFS('Profiles Tracker'!E:E,#REF!,'Profiles Tracker'!G:G,Q$1,'Profiles Tracker'!#REF!,"Week 14") -> #REF! | AJ22: =COUNTIFS('Profiles Tracker'!E:E,#REF!,'Profiles Tracker'!G:G,Q$1,'Profiles Tracker'!#REF!,"Week 15") -> #REF! | AK22: =COUNTIFS('Profiles Tracker'!E:E,#REF!,'Profiles Tracker'!G:G,Q$1,'Profiles Tracker'!#REF!,"Week 16") -> #REF! | AL22: =COUNTIFS('Profiles Tracker'!E:E,#REF!,'Profiles Tracker'!G:G,Q$1,'Profiles Tracker'!#REF!,"Week 17") -> #REF! | AM22: =COUNTIFS('Profiles Tracker'!E:E,#REF!,'Profiles Tracker'!G:G,Q$1,'Profiles Tracker'!#REF!,"Week 18") -> #REF!
A23: =ROW()-1 -> 22 | B23: ADCL | C23: Planning & QS | E23: 45668 | F23: Sr.Engineer ( QS ) | G23: 18 | H23: 45716 | I23: Mr. Subash | J23: Mr. Ravindra Varma | K23: ANY-20 | L23: ADCL-22 | M23: APM Below | N23: =COUNTIFS('Profiles Tracker'!E:E,#REF!,'Profiles Tracker'!G:G,"Profile shared with Interviewer") -> 0 | O23: =COUNTIFS('Profiles Tracker'!E:E,#REF!,'Profiles Tracker'!G:G,"Shortlisted for next round of interview") -> 0 | P23: =COUNTIFS('Profiles Tracker'!E:E,#REF!,'Profiles Tracker'!G:G,P$1) -> 0 | Q23: =COUNTIFS('Profiles Tracker'!E:E,#REF!,'Profiles Tracker'!G:G,Q$1) -> 0 | R23: =COUNTIFS('Profiles Tracker'!E:E,#REF!,'Profiles Tracker'!G:G,R$1) -> 0 | S23: =COUNTIFS('Profiles Tracker'!E:E,#REF!,'Profiles Tracker'!G:G,"Interview Done",'Profiles Tracker'!O:O,"Rejected") -> 0 | T23: =COUNTIFS('Profiles Tracker'!E:E,#REF!,'Profiles Tracker'!G:G,T$1) -> 0 | U23: =N23+P23+Q23+R23+S23+T23 -> 0 | V23: =IF((G23-R23-Q23)<1,0,G23-R23-Q23) -> 18 | W23: =FLOOR(G23,1) -> 18 | X23: =FLOOR(W23,1) -> 18 | Y23: =X23*3 -> 54 | Z23: =IF(W23-SUM(Q23:R23)<1,0,W23-SUM(Q23:R23)) -> 18 | AA23: =IF(X23-SUM(P23:R23)<1,0,X23-SUM(P23:R23)) -> 18 | AB23: =IF(AA23*3-N23<1,0,AA23*3-N23) -> 54 | AC23: =IF(M23="APM Below",H23-45,IF(M23="APM & Above", H23-60,H23-90)) -> 45671 | AD23: =IFERROR(AC23-5,"NA") -> 45666 | AE23: =IFERROR(AD23-7,"NA") -> 45659 | AF23: =CEILING((AC23-TODAY())/7,1) -> -63 | AG23: =CEILING((AD23-TODAY())/7,1) -> -64 | AH23: =CEILING((AE23-TODAY())/7,1) -> -65 | AI23: =COUNTIFS('Profiles Tracker'!E:E,#REF!,'Profiles Tracker'!G:G,Q$1,'Profiles Tracker'!#REF!,"Week 14") -> #REF! | AJ23: =COUNTIFS('Profiles Tracker'!E:E,#REF!,'Profiles Tracker'!G:G,Q$1,'Profiles Tracker'!#REF!,"Week 15") -> #REF! | AK23: =COUNTIFS('Profiles Tracker'!E:E,#REF!,'Profiles Tracker'!G:G,Q$1,'Profiles Tracker'!#REF!,"Week 16") -> #REF! | AL23: =COUNTIFS('Profiles Tracker'!E:E,#REF!,'Profiles Tracker'!G:G,Q$1,'Profiles Tracker'!#REF!,"Week 17") -> #REF! | AM23: =COUNTIFS('Profiles Tracker'!E:E,#REF!,'Profiles Tracker'!G:G,Q$1,'Profiles Tracker'!#REF!,"Week 18") -> #REF!
A24: =ROW()-1 -> 23 | B24: ADCL | C24: Planning & QS | E24: 45668 | F24: Asst Engineer ( QS ) | G24: 20 | H24: 45716 | I24: Mr. Subash | J24: Mr. Ravindra Varma | K24: ANY-21 | L24: ADCL-23 | M24: APM Below | N24: =COUNTIFS('Profiles Tracker'!E:E,#REF!,'Profiles Tracker'!G:G,"Profile shared with Interviewer") -> 0 | O24: =COUNTIFS('Profiles Tracker'!E:E,#REF!,'Profiles Tracker'!G:G,"Shortlisted for next round of interview") -> 0 | P24: =COUNTIFS('Profiles Tracker'!E:E,#REF!,'Profiles Tracker'!G:G,P$1) -> 0 | Q24: =COUNTIFS('Profiles Tracker'!E:E,#REF!,'Profiles Tracker'!G:G,Q$1) -> 0 | R24: =COUNTIFS('Profiles Tracker'!E:E,#REF!,'Profiles Tracker'!G:G,R$1) -> 0 | S24: =COUNTIFS('Profiles Tracker'!E:E,#REF!,'Profiles Tracker'!G:G,"Interview Done",'Profiles Tracker'!O:O,"Rejected") -> 0 | T24: =COUNTIFS('Profiles Tracker'!E:E,#REF!,'Profiles Tracker'!G:G,T$1) -> 0 | U24: =N24+P24+Q24+R24+S24+T24 -> 0 | V24: =IF((G24-R24-Q24)<1,0,G24-R24-Q24) -> 20 | W24: =FLOOR(G24,1) -> 20 | X24: =FLOOR(W24,1) -> 20 | Y24: =X24*3 -> 60 | Z24: =IF(W24-SUM(Q24:R24)<1,0,W24-SUM(Q24:R24)) -> 20 | AA24: =IF(X24-SUM(P24:R24)<1,0,X24-SUM(P24:R24)) -> 20 | AB24: =IF(AA24*3-N24<1,0,AA24*3-N24) -> 60 | AC24: =IF(M24="APM Below",H24-45,IF(M24="APM & Above", H24-60,H24-90)) -> 45671 | AD24: =IFERROR(AC24-5,"NA") -> 45666 | AE24: =IFERROR(AD24-7,"NA") -> 45659 | AF24: =CEILING((AC24-TODAY())/7,1) -> -63 | AG24: =CEILING((AD24-TODAY())/7,1) -> -64 | AH24: =CEILING((AE24-TODAY())/7,1) -> -65 | AI24: =COUNTIFS('Profiles Tracker'!E:E,#REF!,'Profiles Tracker'!G:G,Q$1,'Profiles Tracker'!#REF!,"Week 14") -> #REF! | AJ24: =COUNTIFS('Profiles Tracker'!E:E,#REF!,'Profiles Tracker'!G:G,Q$1,'Profiles Tracker'!#REF!,"Week 15") -> #REF! | AK24: =COUNTIFS('Profiles Tracker'!E:E,#REF!,'Profiles Tracker'!G:G,Q$1,'Profiles Tracker'!#REF!,"Week 16") -> #REF! | AL24: =COUNTIFS('Profiles Tracker'!E:E,#REF!,'Profiles Tracker'!G:G,Q$1,'Profiles Tracker'!#REF!,"Week 17") -> #REF! | AM24: =COUNTIFS('Profiles Tracker'!E:E,#REF!,'Profiles Tracker'!G:G,Q$1,'Profiles Tracker'!#REF!,"Week 18") -> #REF!
A25: =ROW()-1 -> 24 | B25: ADCL | C25: Stores | E25: 45668 | F25: Sr. Manager ( Stores & Procurement ) | G25: 1 | H25: 45716 | I25: Mr. Y Srinivas Rao | J25: Mr. Ravindra Varma | K25: ANY-23 | L25: ADCL-24 | M25: APM & Above | N25: =COUNTIFS('Profiles Tracker'!E:E,#REF!,'Profiles Tracker'!G:G,"Profile shared with Interviewer") -> 0 | O25: =COUNTIFS('Profiles Tracker'!E:E,#REF!,'Profiles Tracker'!G:G,"Shortlisted for next round of interview") -> 0 | P25: =COUNTIFS('Profiles Tracker'!E:E,#REF!,'Profiles Tracker'!G:G,P$1) -> 0 | Q25: =COUNTIFS('Profiles Tracker'!E:E,#REF!,'Profiles Tracker'!G:G,Q$1) -> 0 | R25: =COUNTIFS('Profiles Tracker'!E:E,#REF!,'Profiles Tracker'!G:G,R$1) -> 0 | S25: =COUNTIFS('Profiles Tracker'!E:E,#REF!,'Profiles Tracker'!G:G,"Interview Done",'Profiles Tracker'!O:O,"Rejected") -> 0 | T25: =COUNTIFS('Profiles Tracker'!E:E,#REF!,'Profiles Tracker'!G:G,T$1) -> 0 | U25: =N25+P25+Q25+R25+S25+T25 -> 0 | V25: =IF((G25-R25-Q25)<1,0,G25-R25-Q25) -> 1 | W25: =FLOOR(G25,1) -> 1 | X25: =FLOOR(W25,1) -> 1 | Y25: =X25*3 -> 3 | Z25: =IF(W25-SUM(Q25:R25)<1,0,W25-SUM(Q25:R25)) -> 1 | AA25: =IF(X25-SUM(P25:R25)<1,0,X25-SUM(P25:R25)) -> 1 | AB25: =IF(AA25*3-N25<1,0,AA25*3-N25) -> 3 | AC25: =IF(M25="APM Below",H25-45,IF(M25="APM & Above", H25-60,H25-90)) -> 45656 | AD25: =IFERROR(AC25-5,"NA") -> 45651 | AE25: =IFERROR(AD25-7,"NA") -> 45644 | AF25: =CEILING((AC25-TODAY())/7,1) -> -65 | AG25: =CEILING((AD25-TODAY())/7,1) -> -66 | AH25: =CEILING((AE25-TODAY())/7,1) -> -67 | AI25: =COUNTIFS('Profiles Tracker'!E:E,#REF!,'Profiles Tracker'!G:G,Q$1,'Profiles Tracker'!#REF!,"Week 14") -> #REF! | AJ25: =COUNTIFS('Profiles Tracker'!E:E,#REF!,'Profiles Tracker'!G:G,Q$1,'Profiles Tracker'!#REF!,"Week 15") -> #REF! | AK25: =COUNTIFS('Profiles Tracker'!E:E,#REF!,'Profiles Tracker'!G:G,Q$1,'Profiles Tracker'!#REF!,"Week 16") -> #REF! | AL25: =COUNTIFS('Profiles Tracker'!E:E,#REF!,'Profiles Tracker'!G:G,Q$1,'Profiles Tracker'!#REF!,"Week 17") -> #REF! | AM25: =COUNTIFS('Profiles Tracker'!E:E,#REF!,'Profiles Tracker'!G:G,Q$1,'Profiles Tracker'!#REF!,"Week 18") -> #REF!
A26: =ROW()-1 -> 25 | B26: ADCL | C26: Stores | E26: 45668 | F26: Manager Stores | G26: 1 | H26: 45716 | I26: Mr. Y Srinivas Rao | J26: Mr. Ravindra Varma | K26: ANY-24 | L26: ADCL-25 | M26: APM & Above | N26: =COUNTIFS('Profiles Tracker'!E:E,#REF!,'Profiles Tracker'!G:G,"Profile shared with Interviewer") -> 0 | O26: =COUNTIFS('Profiles Tracker'!E:E,#REF!,'Profiles Tracker'!G:G,"Shortlisted for next round of interview") -> 0 | P26: =COUNTIFS('Profiles Tracker'!E:E,#REF!,'Profiles Tracker'!G:G,P$1) -> 0 | Q26: =COUNTIFS('Profiles Tracker'!E:E,#REF!,'Profiles Tracker'!G:G,Q$1) -> 0 | R26: =COUNTIFS('Profiles Tracker'!E:E,#REF!,'Profiles Tracker'!G:G,R$1) -> 0 | S26: =COUNTIFS('Profiles Tracker'!E:E,#REF!,'Profiles Tracker'!G:G,"Interview Done",'Profiles Tracker'!O:O,"Rejected") -> 0 | T26: =COUNTIFS('Profiles Tracker'!E:E,#REF!,'Profiles Tracker'!G:G,T$1) -> 0 | U26: =N26+P26+Q26+R26+S26+T26 -> 0 | V26: =IF((G26-R26-Q26)<1,0,G26-R26-Q26) -> 1 | W26: =FLOOR(G26,1) -> 1 | X26: =FLOOR(W26,1) -> 1 | Y26: =X26*3 -> 3 | Z26: =IF(W26-SUM(Q26:R26)<1,0,W26-SUM(Q26:R26)) -> 1 | AA26: =IF(X26-SUM(P26:R26)<1,0,X26-SUM(P26:R26)) -> 1 | AB26: =IF(AA26*3-N26<1,0,AA26*3-N26) -> 3 | AC26: =IF(M26="APM Below",H26-45,IF(M26="APM & Above", H26-60,H26-90)) -> 45656 | AD26: =IFERROR(AC26-5,"NA") -> 45651 | AE26: =IFERROR(AD26-7,"NA") -> 45644 | AF26: =CEILING((AC26-TODAY())/7,1) -> -65 | AG26: =CEILING((AD26-TODAY())/7,1) -> -66 | AH26: =CEILING((AE26-TODAY())/7,1) -> -67 | AI26: =COUNTIFS('Profiles Tracker'!E:E,#REF!,'Profiles Tracker'!G:G,Q$1,'Profiles Tracker'!#REF!,"Week 14") -> #REF! | AJ26: =COUNTIFS('Profiles Tracker'!E:E,#REF!,'Profiles Tracker'!G:G,Q$1,'Profiles Tracker'!#REF!,"Week 15") -> #REF! | AK26: =COUNTIFS('Profiles Tracker'!E:E,#REF!,'Profiles Tracker'!G:G,Q$1,'Profiles Tracker'!#REF!,"Week 16") -> #REF! | AL26: =COUNTIFS('Profiles Tracker'!E:E,#REF!,'Profiles Tracker'!G:G,Q$1,'Profiles Tracker'!#REF!,"Week 17") -> #REF! | AM26: =COUNTIFS('Profiles Tracker'!E:E,#REF!,'Profiles Tracker'!G:G,Q$1,'Profiles Tracker'!#REF!,"Week 18") -> #REF!
... A37: =ROW()-1 -> 36 | B37: ADCL | C37: Earthwork | E37: 45668 | F37: Project Manager ( Earthwork) | G37: 1 | H37: 45716 | I37: Mr. Raghu Rama Raju | J37: Mr. Ravindra Varma | K37: ANY-35 | L37: ADCL-36 | M37: APM & Above | N37: =COUNTIFS('Profiles Tracker'!E:E,#REF!,'Profiles Tracker'!G:G,"Profile shared with Interviewer") -> 0 | O37: =COUNTIFS('Profiles Tracker'!E:E,#REF!,'Profiles Tracker'!G:G,"Shortlisted for next round of interview") -> 0 | P37: =COUNTIFS('Profiles Tracker'!E:E,#REF!,'Profiles Tracker'!G:G,P$1) -> 0 | Q37: =COUNTIFS('Profiles Tracker'!E:E,#REF!,'Profiles Tracker'!G:G,Q$1) -> 0 | R37: =COUNTIFS('Profiles Tracker'!E:E,#REF!,'Profiles Tracker'!G:G,R$1) -> 0 | S37: =COUNTIFS('Profiles Tracker'!E:E,#REF!,'Profiles Tracker'!G:G,"Interview Done",'Profiles Tracker'!O:O,"Rejected") -> 0 | T37: =COUNTIFS('Profiles Tracker'!E:E,#REF!,'Profiles Tracker'!G:G,T$1) -> 0 | U37: =N37+P37+Q37+R37+S37+T37 -> 0 | V37: =IF((G37-R37-Q37)<1,0,G37-R37-Q37) -> 1 | W37: =FLOOR(G37,1) -> 1 | X37: =FLOOR(W37,1) -> 1 | Y37: =X37*3 -> 3 | Z37: =IF(W37-SUM(Q37:R37)<1,0,W37-SUM(Q37:R37)) -> 1 | AA37: =IF(X37-SUM(P37:R37)<1,0,X37-SUM(P37:R37)) -> 1 | AB37: =IF(AA37*3-N37<1,0,AA37*3-N37) -> 3 | AC37: =IF(M37="APM Below",H37-45,IF(M37="APM & Above", H37-60,H37-90)) -> 45656 | AD37: =IFERROR(AC37-5,"NA") -> 45651 | AE37: =IFERROR(AD37-7,"NA") -> 45644 | AF37: =CEILING((AC37-TODAY())/7,1) -> -65 | AG37: =CEILING((AD37-TODAY())/7,1) -> -66 | AH37: =CEILING((AE37-TODAY())/7,1) -> -67 | AI37: =COUNTIFS('Profiles Tracker'!E:E,#REF!,'Profiles Tracker'!G:G,Q$1,'Profiles Tracker'!#REF!,"Week 14") -> #REF! | AJ37: =COUNTIFS('Profiles Tracker'!E:E,#REF!,'Profiles Tracker'!G:G,Q$1,'Profiles Tracker'!#REF!,"Week 15") -> #REF! | AK37: =COUNTIFS('Profiles Tracker'!E:E,#REF!,'Profiles Tracker'!G:G,Q$1,'Profiles Tracker'!#REF!,"Week 16") -> #REF! | AL37: =COUNTIFS('Profiles Tracker'!E:E,#REF!,'Profiles Tracker'!G:G,Q$1,'Profiles Tracker'!#REF!,"Week 17") -> #REF! | AM37: =COUNTIFS('Profiles Tracker'!E:E,#REF!,'Profiles Tracker'!G:G,Q$1,'Profiles Tracker'!#REF!,"Week 18") -> #REF!
A38: =ROW()-1 -> 37 | B38: ADCL | C38: Earthwork | E38: 45668 | F38: Sr.Engineers ( Earthwork ) | G38: 0 | H38: 45716 | I38: Mr. Raghu Rama Raju | J38: Mr. Ravindra Varma | K38: ANY-36 | M38: APM Below | N38: =COUNTIFS('Profiles Tracker'!E:E,#REF!,'Profiles Tracker'!G:G,"Profile shared with Interviewer") -> 0 | O38: =COUNTIFS('Profiles Tracker'!E:E,#REF!,'Profiles Tracker'!G:G,"Shortlisted for next round of interview") -> 0 | P38: =COUNTIFS('Profiles Tracker'!E:E,#REF!,'Profiles Tracker'!G:G,P$1) -> 0 | Q38: =COUNTIFS('Profiles Tracker'!E:E,#REF!,'Profiles Tracker'!G:G,Q$1) -> 0 | R38: =COUNTIFS('Profiles Tracker'!E:E,#REF!,'Profiles Tracker'!G:G,R$1) -> 0 | S38: =COUNTIFS('Profiles Tracker'!E:E,#REF!,'Profiles Tracker'!G:G,"Interview Done",'Profiles Tracker'!O:O,"Rejected") -> 0 | T38: =COUNTIFS('Profiles Tracker'!E:E,#REF!,'Profiles Tracker'!G:G,T$1) -> 0 | U38: =N38+P38+Q38+R38+S38+T38 -> 0 | V38: =IF((G38-R38-Q38)<1,0,G38-R38-Q38) -> 0 | W38: =FLOOR(G38,1) -> 0 | X38: =FLOOR(W38,1) -> 0 | Y38: =X38*3 -> 0 | Z38: =IF(W38-SUM(Q38:R38)<1,0,W38-SUM(Q38:R38)) -> 0 | AA38: =IF(X38-SUM(P38:R38)<1,0,X38-SUM(P38:R38)) -> 0 | AB38: =IF(AA38*3-N38<1,0,AA38*3-N38) -> 0 | AC38: =IF(M38="APM Below",H38-45,IF(M38="APM & Above", H38-60,H38-90)) -> 45671 | AD38: =IFERROR(AC38-5,"NA") -> 45666 | AE38: =IFERROR(AD38-7,"NA") -> 45659 | AF38: =CEILING((AC38-TODAY())/7,1) -> -63 | AG38: =CEILING((AD38-TODAY())/7,1) -> -64 | AH38: =CEILING((AE38-TODAY())/7,1) -> -65 | AI38: =COUNTIFS('Profiles Tracker'!E:E,#REF!,'Profiles Tracker'!G:G,Q$1,'Profiles Tracker'!#REF!,"Week 14") -> #REF! | AJ38: =COUNTIFS('Profiles Tracker'!E:E,#REF!,'Profiles Tracker'!G:G,Q$1,'Profiles Tracker'!#REF!,"Week 15") -> #REF! | AK38: =COUNTIFS('Profiles Tracker'!E:E,#REF!,'Profiles Tracker'!G:G,Q$1,'Profiles Tracker'!#REF!,"Week 16") -> #REF! | AL38: =COUNTIFS('Profiles Tracker'!E:E,#REF!,'Profiles Tracker'!G:G,Q$1,'Profiles Tracker'!#REF!,"Week 17") -> #REF! | AM38: =COUNTIFS('Profiles Tracker'!E:E,#REF!,'Profiles Tracker'!G:G,Q$1,'Profiles Tracker'!#REF!,"Week 18") -> #REF!
A39: =ROW()-1 -> 38 | B39: ADCL | C39: Structures | E39: 45668 | F39: Jr.Engineer ( structures) | H39: 45716 | I39: Mr. Radha Krishna (Consultant) | J39: Mr. Venu | K39: ANY-37 | M39: APM Below | N39: =COUNTIFS('Profiles Tracker'!E:E,#REF!,'Profiles Tracker'!G:G,"Profile shared with Interviewer") -> 0 | O39: =COUNTIFS('Profiles Tracker'!E:E,#REF!,'Profiles Tracker'!G:G,"Shortlisted for next round of interview") -> 0 | P39: =COUNTIFS('Profiles Tracker'!E:E,#REF!,'Profiles Tracker'!G:G,P$1) -> 0 | Q39: =COUNTIFS('Profiles Tracker'!E:E,#REF!,'Profiles Tracker'!G:G,Q$1) -> 0 | R39: =COUNTIFS('Profiles Tracker'!E:E,#REF!,'Profiles Tracker'!G:G,R$1) -> 0 | S39: =COUNTIFS('Profiles Tracker'!E:E,#REF!,'Profiles Tracker'!G:G,"Interview Done",'Profiles Tracker'!O:O,"Rejected") -> 0 | T39: =COUNTIFS('Profiles Tracker'!E:E,#REF!,'Profiles Tracker'!G:G,T$1) -> 0 | U39: =N39+P39+Q39+R39+S39+T39 -> 0 | V39: =IF((G39-R39-Q39)<1,0,G39-R39-Q39) -> 0 | W39: =FLOOR(G39,1) -> 0 | X39: =FLOOR(W39,1) -> 0 | Y39: =X39*3 -> 0 | Z39: =IF(W39-SUM(Q39:R39)<1,0,W39-SUM(Q39:R39)) -> 0 | AA39: =IF(X39-SUM(P39:R39)<1,0,X39-SUM(P39:R39)) -> 0 | AB39: =IF(AA39*3-N39<1,0,AA39*3-N39) -> 0 | AC39: =IF(M39="APM Below",H39-45,IF(M39="APM & Above", H39-60,H39-90)) -> 45671 | AD39: =IFERROR(AC39-5,"NA") -> 45666 | AE39: =IFERROR(AD39-7,"NA") -> 45659 | AF39: =CEILING((AC39-TODAY())/7,1) -> -63 | AG39: =CEILING((AD39-TODAY())/7,1) -> -64 | AH39: =CEILING((AE39-TODAY())/7,1) -> -65 | AI39: =COUNTIFS('Profiles Tracker'!E:E,#REF!,'Profiles Tracker'!G:G,Q$1,'Profiles Tracker'!#REF!,"Week 14") -> #REF! | AJ39: =COUNTIFS('Profiles Tracker'!E:E,#REF!,'Profiles Tracker'!G:G,Q$1,'Profiles Tracker'!#REF!,"Week 15") -> #REF! | AK39: =COUNTIFS('Profiles Tracker'!E:E,#REF!,'Profiles Tracker'!G:G,Q$1,'Profiles Tracker'!#REF!,"Week 16") -> #REF! | AL39: =COUNTIFS('Profiles Tracker'!E:E,#REF!,'Profiles Tracker'!G:G,Q$1,'Profiles Tracker'!#REF!,"Week 17") -> #REF! | AM39: =COUNTIFS('Profiles Tracker'!E:E,#REF!,'Profiles Tracker'!G:G,Q$1,'Profiles Tracker'!#REF!,"Week 18") -> #REF!
A40: =ROW()-1 -> 39 | B40: ADCL | E40: 45668 | F40: Supervisors | G40: 2 | H40: 45716 | I40: Mr. Madhusudhan Reddy | J40: Mr. Ravindra Varma | K40: ANY-38 | M40: APM Below | N40: =COUNTIFS('Profiles Tracker'!E:E,#REF!,'Profiles Tracker'!G:G,"Profile shared with Interviewer") -> 0 | O40: =COUNTIFS('Profiles Tracker'!E:E,#REF!,'Profiles Tracker'!G:G,"Shortlisted for next round of interview") -> 0 | P40: =COUNTIFS('Profiles Tracker'!E:E,#REF!,'Profiles Tracker'!G:G,P$1) -> 0 | Q40: =COUNTIFS('Profiles Tracker'!E:E,#REF!,'Profiles Tracker'!G:G,Q$1) -> 0 | R40: =COUNTIFS('Profiles Tracker'!E:E,#REF!,'Profiles Tracker'!G:G,R$1) -> 0 | S40: =COUNTIFS('Profiles Tracker'!E:E,#REF!,'Profiles Tracker'!G:G,"Interview Done",'Profiles Tracker'!O:O,"Rejected") -> 0 | T40: =COUNTIFS('Profiles Tracker'!E:E,#REF!,'Profiles Tracker'!G:G,T$1) -> 0 | U40: =N40+P40+Q40+R40+S40+T40 -> 0 | V40: =IF((G40-R40-Q40)<1,0,G40-R40-Q40) -> 2 | W40: =FLOOR(G40,1) -> 2 | X40: =FLOOR(W40,1) -> 2 | Y40: =X40*3 -> 6 | Z40: =IF(W40-SUM(Q40:R40)<1,0,W40-SUM(Q40:R40)) -> 2 | AA40: =IF(X40-SUM(P40:R40)<1,0,X40-SUM(P40:R40)) -> 2 | AB40: =IF(AA40*3-N40<1,0,AA40*3-N40) -> 6 | AC40: =IF(M40="APM Below",H40-45,IF(M40="APM & Above", H40-60,H40-90)) -> 45671 | AD40: =IFERROR(AC40-5,"NA") -> 45666 | AE40: =IFERROR(AD40-7,"NA") -> 45659 | AF40: =CEILING((AC40-TODAY())/7,1) -> -63 | AG40: =CEILING((AD40-TODAY())/7,1) -> -64 | AH40: =CEILING((AE40-TODAY())/7,1) -> -65 | AI40: =COUNTIFS('Profiles Tracker'!E:E,#REF!,'Profiles Tracker'!G:G,Q$1,'Profiles Tracker'!#REF!,"Week 14") -> #REF! | AJ40: =COUNTIFS('Profiles Tracker'!E:E,#REF!,'Profiles Tracker'!G:G,Q$1,'Profiles Tracker'!#REF!,"Week 15") -> #REF! | AK40: =COUNTIFS('Profiles Tracker'!E:E,#REF!,'Profiles Tracker'!G:G,Q$1,'Profiles Tracker'!#REF!,"Week 16") -> #REF! | AL40: =COUNTIFS('Profiles Tracker'!E:E,#REF!,'Profiles Tracker'!G:G,Q$1,'Profiles Tracker'!#REF!,"Week 17") -> #REF! | AM40: =COUNTIFS('Profiles Tracker'!E:E,#REF!,'Profiles Tracker'!G:G,Q$1,'Profiles Tracker'!#REF!,"Week 18") -> #REF!
