Workbook

Sheet ADCL Codes Updated
A1: S.No | B1: Project | C1: Nature of work | D1: Department | E1: Indent Date | F1: Role | G1: Total Req | H1: Required By Date | I1: Interview Panel | J1: HR SPOC | K1: Job ID | M1: Level | N1: Interview Pipeline | O1: Second Level Interviews | P1: Offer Negotiation in Process | Q1: Offer Released | R1: Joined | S1: Interview Rejected | T1: Candidate Not Interested | U1: Total Sourcing | V1: Open | W1: Exp Offer Release & further stages Count | X1: Exp Salary Negotiation & Further stages | Y1: Exp Interview Pipeline Count | Z1: Pending Offer Released & further | AA1: Pending Salary Negotiation & Further | AB1: Pending Interview Pipeline & further | AC1: Target Date to close all offers | AD1: Target Date to complete interviews | AE1: Target Date to complete sourcing | AF1: Weeks Remaining to complete offers | AG1: Weeks Remaining to complete interviews | AH1: Weeks Remaining to complete sourcing | AI1: Exp Joinings in Apr 1st Wk | AJ1: Exp Joinings in Apr 2nd Wk | AK1: Exp Joinings in Apr 3rd Wk | AL1: Exp Joinings in Apr 4th Wk | AM1: Exp Joinings in May 1st Wk
A2: =ROW()-1 -> 1 | B2: ADCL | C2: General | E2: 45745 | F2: VP/AVP/SGM | G2: 2 | H2: 45777 | I2: Mr. Raghu Rama Raju | J2: Mr. Ravindra Varma | K2: ANY-113 | L2: ADCL-01 | M2: APM & Above | N2: =COUNTIFS(#REF!,'Requirement List'!$B109,#REF!,"Profile shared with Interviewer") -> #REF! | O2: =COUNTIFS(#REF!,'Requirement List'!$B109,#REF!,"Shortlisted for next round of interview") -> #REF! | P2: =COUNTIFS(#REF!,'Requirement List'!$B109,#REF!,P$1) -> #REF! | Q2: =COUNTIFS(#REF!,'Requirement List'!$B109,#REF!,Q$1) -> #REF! | R2: =COUNTIFS(#REF!,'Requirement List'!$B109,#REF!,R$1) -> #REF! | S2: =COUNTIFS(#REF!,'Requirement List'!$B109,#REF!,"Interview Done",#REF!,"Rejected") -> #REF! | T2: =COUNTIFS(#REF!,'Requirement List'!$B109,#REF!,T$1) -> #REF! | U2: =N2+P2+Q2+R2+S2+T2 -> #REF! | V2: =IF((G2-R2-Q2)<1,0,G2-R2-Q2) -> #REF! | W2: =FLOOR(G2,1) -> 2 | X2: =FLOOR(W2,1) -> 2 | Y2: =X2*3 -> 6 | Z2: =IF(W2-SUM(Q2:R2)<1,0,W2-SUM(Q2:R2)) -> #REF! | AA2: =IF(X2-SUM(P2:R2)<1,0,X2-SUM(P2:R2)) -> #REF! | AB2: =IF(AA2*3-N2<1,0,AA2*3-N2) -> #REF! | AC2: =IF(M2="APM Below",H2-45,IF(M2="APM & Above", H2-60,H2-90)) -> 45717 | AD2: =IFERROR(AC2-5,"NA") -> 45712 | AE2: =IFERROR(AD2-7,"NA") -> 45705 | AF2: =CEILING((AC2-TODAY())/7,1) -> -56 | AG2: =CEILING((AD2-TODAY())/7,1) -> -57 | AH2: =CEILING((AE2-TODAY())/7,1) -> -58 | AI2: =COUNTIFS(#REF!,'Requirement List'!$B109,#REF!,Q$1,#REF!,"Week 14") -> #REF! | AJ2: =COUNTIFS(#REF!,'Requirement List'!$B109,#REF!,Q$1,#REF!,"Week 15") -> #REF! | AK2: =COUNTIFS(#REF!,'Requirement List'!$B109,#REF!,Q$1,#REF!,"Week 16") -> #REF! | AL2: =COUNTIFS(#REF!,'Requirement List'!$B109,#REF!,Q$1,#REF!,"Week 17") -> #REF! | AM2: =COUNTIFS(#REF!,'Requirement List'!$B109,#REF!,Q$1,#REF!,"Week 18") -> #REF!
A3: =ROW()-1 -> 2 | B3: ADCL | C3: General | E3: 45668 | F3: General Manager | G3: 1 | H3: 45716 | I3: Mr. Raghu Rama Raju | J3: Mr. Ravindra Varma | K3: ANY-01 | L3: ADCL-02 | M3: APM & Above | N3: =COUNTIFS(#REF!,'Requirement List'!$B2,#REF!,"Profile shared with Interviewer") -> #REF! | O3: =COUNTIFS(#REF!,'Requirement List'!$B2,#REF!,"Shortlisted for next round of interview") -> #REF! | P3: =COUNTIFS(#REF!,'Requirement List'!$B2,#REF!,P$1) -> #REF! | Q3: =COUNTIFS(#REF!,'Requirement List'!$B2,#REF!,Q$1) -> #REF! | R3: =COUNTIFS(#REF!,'Requirement List'!$B2,#REF!,R$1) -> #REF! | S3: =COUNTIFS(#REF!,'Requirement List'!$B2,#REF!,"Interview Done",#REF!,"Rejected") -> #REF! | T3: =COUNTIFS(#REF!,'Requirement List'!$B2,#REF!,T$1) -> #REF! | U3: =N3+P3+Q3+R3+S3+T3 -> #REF! | V3: =IF((G3-R3-Q3)<1,0,G3-R3-Q3) -> #REF! | W3: =FLOOR(G3,1) -> 1 | X3: =FLOOR(W3,1) -> 1 | Y3: =X3*3 -> 3 | Z3: =IF(W3-SUM(Q3:R3)<1,0,W3-SUM(Q3:R3)) -> #REF! | AA3: =IF(X3-SUM(P3:R3)<1,0,X3-SUM(P3:R3)) -> #REF! | AB3: =IF(AA3*3-N3<1,0,AA3*3-N3) -> #REF! | AC3: =IF(M3="APM Below",H3-45,IF(M3="APM & Above", H3-60,H3-90)) -> 45656 | AD3: =IFERROR(AC3-5,"NA") -> 45651 | AE3: =IFERROR(AD3-7,"NA") -> 45644 | AF3: =CEILING((AC3-TODAY())/7,1) -> -65 | AG3: =CEILING((AD3-TODAY())/7,1) -> -66 | AH3: =CEILING((AE3-TODAY())/7,1) -> -67 | AI3: =COUNTIFS(#REF!,'Requirement List'!$B2,#REF!,Q$1,#REF!,"Week 14") -> #REF! | AJ3: =COUNTIFS(#REF!,'Requirement List'!$B2,#REF!,Q$1,#REF!,"Week 15") -> #REF! | AK3: =COUNTIFS(#REF!,'Requirement List'!$B2,#REF!,Q$1,#REF!,"Week 16") -> #REF! | AL3: =COUNTIFS(#REF!,'Requirement List'!$B2,#REF!,Q$1,#REF!,"Week 17") -> #REF! | AM3: =COUNTIFS(#REF!,'Requirement List'!$B2,#REF!,Q$1,#REF!,"Week 18") -> #REF!
A4: =ROW()-1 -> 3 | B4: ADCL | C4: Roads | E4: 45668 | F4: PM ( Structures & Roads ) | G4: 9 | H4: 45716 | I4: Mr. Raghu Rama Raju | J4: Mr. Ravindra Varma | K4: ANY-02 | L4: ADCL-03 | M4: APM & Above | N4: =COUNTIFS(#REF!,'Requirement List'!$B3,#REF!,"Profile shared with Interviewer") -> #REF! | O4: =COUNTIFS(#REF!,'Requirement List'!$B3,#REF!,"Shortlisted for next round of interview") -> #REF! | P4: =COUNTIFS(#REF!,'Requirement List'!$B3,#REF!,P$1) -> #REF! | Q4: =COUNTIFS(#REF!,'Requirement List'!$B3,#REF!,Q$1) -> #REF! | R4: =COUNTIFS(#REF!,'Requirement List'!$B3,#REF!,R$1) -> #REF! | S4: =COUNTIFS(#REF!,'Requirement List'!$B3,#REF!,"Interview Done",#REF!,"Rejected") -> #REF! | T4: =COUNTIFS(#REF!,'Requirement List'!$B3,#REF!,T$1) -> #REF! | U4: =N4+P4+Q4+R4+S4+T4 -> #REF! | V4: =IF((G4-R4-Q4)<1,0,G4-R4-Q4) -> #REF! | W4: =FLOOR(G4,1) -> 9 | X4: =FLOOR(W4,1) -> 9 | Y4: =X4*3 -> 27 | Z4: =IF(W4-SUM(Q4:R4)<1,0,W4-SUM(Q4:R4)) -> #REF! | AA4: =IF(X4-SUM(P4:R4)<1,0,X4-SUM(P4:R4)) -> #REF! | AB4: =IF(AA4*3-N4<1,0,AA4*3-N4) -> #REF! | AC4: =IF(M4="APM Below",H4-45,IF(M4="APM & Above", H4-60,H4-90)) -> 45656 | AD4: =IFERROR(AC4-5,"NA") -> 45651 | AE4: =IFERROR(AD4-7,"NA") -> 45644 | AF4: =CEILING((AC4-TODAY())/7,1) -> -65 | AG4: =CEILING((AD4-TODAY())/7,1) -> -66 | AH4: =CEILING((AE4-TODAY())/7,1) -> -67 | AI4: =COUNTIFS(#REF!,'Requirement List'!$B3,#REF!,Q$1,#REF!,"Week 14") -> #REF! | AJ4: =COUNTIFS(#REF!,'Requirement List'!$B3,#REF!,Q$1,#REF!,"Week 15") -> #REF! | AK4: =COUNTIFS(#REF!,'Requirement List'!$B3,#REF!,Q$1,#REF!,"Week 16") -> #REF! | AL4: =COUNTIFS(#REF!,'Requirement List'!$B3,#REF!,Q$1,#REF!,"Week 17") -> #REF! | AM4: =COUNTIFS(#REF!,'Requirement List'!$B3,#REF!,Q$1,#REF!,"Week 18") -> #REF!
A5: =ROW()-1 -> 4 | B5: ADCL | C5: Structures | E5: 45668 | F5: DPM Structures | G5: 11 | H5: 45716 | I5: Mr. Raghu Rama Raju | J5: Mr. Ravindra Varma | K5: ANY-03 | L5: ADCL-04 | M5: APM & Above | N5: =COUNTIFS(#REF!,'Requirement List'!$B4,#REF!,"Profile shared with Interviewer") -> #REF! | O5: =COUNTIFS(#REF!,'Requirement List'!$B4,#REF!,"Shortlisted for next round of interview") -> #REF! | P5: =COUNTIFS(#REF!,'Requirement List'!$B4,#REF!,P$1) -> #REF! | Q5: =COUNTIFS(#REF!,'Requirement List'!$B4,#REF!,Q$1) -> #REF! | R5: =COUNTIFS(#REF!,'Requirement List'!$B4,#REF!,R$1) -> #REF! | S5: =COUNTIFS(#REF!,'Requirement List'!$B4,#REF!,"Interview Done",#REF!,"Rejected") -> #REF! | T5: =COUNTIFS(#REF!,'Requirement List'!$B4,#REF!,T$1) -> #REF! | U5: =N5+P5+Q5+R5+S5+T5 -> #REF! | V5: =IF((G5-R5-Q5)<1,0,G5-R5-Q5) -> #REF! | W5: =FLOOR(G5,1) -> 11 | X5: =FLOOR(W5,1) -> 11 | Y5: =X5*3 -> 33 | Z5: =IF(W5-SUM(Q5:R5)<1,0,W5-SUM(Q5:R5)) -> #REF! | AA5: =IF(X5-SUM(P5:R5)<1,0,X5-SUM(P5:R5)) -> #REF! | AB5: =IF(AA5*3-N5<1,0,AA5*3-N5) -> #REF! | AC5: =IF(M5="APM Below",H5-45,IF(M5="APM & Above", H5-60,H5-90)) -> 45656 | AD5: =IFERROR(AC5-5,"NA") -> 45651 | AE5: =IFERROR(AD5-7,"NA") -> 45644 | AF5: =CEILING((AC5-TODAY())/7,1) -> -65 | AG5: =CEILING((AD5-TODAY())/7,1) -> -66 | AH5: =CEILING((AE5-TODAY())/7,1) -> -67 | AI5: =COUNTIFS(#REF!,'Requirement List'!$B4,#REF!,Q$1,#REF!,"Week 14") -> #REF! | AJ5: =COUNTIFS(#REF!,'Requirement List'!$B4,#REF!,Q$1,#REF!,"Week 15") -> #REF! | AK5: =COUNTIFS(#REF!,'Requirement List'!$B4,#REF!,Q$1,#REF!,"Week 16") -> #REF! | AL5: =COUNTIFS(#REF!,'Requirement List'!$B4,#REF!,Q$1,#REF!,"Week 17") -> #REF! | AM5: =COUNTIFS(#REF!,'Requirement List'!$B4,#REF!,Q$1,#REF!,"Week 18") -> #REF!
A6: =ROW()-1 -> 5 | B6: ADCL | C6: Roads | E6: 45668 | F6: DPM Roads | G6: 13 | H6: 45716 | I6: Mr. Raghu Rama Raju | J6: Mr. Ravindra Varma | K6: ANY-04 | L6: ADCL-05 | M6: APM & Above | N6: =COUNTIFS(#REF!,'Requirement List'!$B5,#REF!,"Profile shared with Interviewer") -> #REF! | O6: =COUNTIFS(#REF!,'Requirement List'!$B5,#REF!,"Shortlisted for next round of interview") -> #REF! | P6: =COUNTIFS(#REF!,'Requirement List'!$B5,#REF!,P$1) -> #REF! | Q6: =COUNTIFS(#REF!,'Requirement List'!$B5,#REF!,Q$1) -> #REF! | R6: =COUNTIFS(#REF!,'Requirement List'!$B5,#REF!,R$1) -> #REF! | S6: =COUNTIFS(#REF!,'Requirement List'!$B5,#REF!,"Interview Done",#REF!,"Rejected") -> #REF! | T6: =COUNTIFS(#REF!,'Requirement List'!$B5,#REF!,T$1) -> #REF! | U6: =N6+P6+Q6+R6+S6+T6 -> #REF! | V6: =IF((G6-R6-Q6)<1,0,G6-R6-Q6) -> #REF! | W6: =FLOOR(G6,1) -> 13 | X6: =FLOOR(W6,1) -> 13 | Y6: =X6*3 -> 39 | Z6: =IF(W6-SUM(Q6:R6)<1,0,W6-SUM(Q6:R6)) -> #REF! | AA6: =IF(X6-SUM(P6:R6)<1,0,X6-SUM(P6:R6)) -> #REF! | AB6: =IF(AA6*3-N6<1,0,AA6*3-N6) -> #REF! | AC6: =IF(M6="APM Below",H6-45,IF(M6="APM & Above", H6-60,H6-90)) -> 45656 | AD6: =IFERROR(AC6-5,"NA") -> 45651 | AE6: =IFERROR(AD6-7,"NA") -> 45644 | AF6: =CEILING((AC6-TODAY())/7,1) -> -65 | AG6: =CEILING((AD6-TODAY())/7,1) -> -66 | AH6: =CEILING((AE6-TODAY())/7,1) -> -67 | AI6: =COUNTIFS(#REF!,'Requirement List'!$B5,#REF!,Q$1,#REF!,"Week 14") -> #REF! | AJ6: =COUNTIFS(#REF!,'Requirement List'!$B5,#REF!,Q$1,#REF!,"Week 15") -> #REF! | AK6: =COUNTIFS(#REF!,'Requirement List'!$B5,#REF!,Q$1,#REF!,"Week 16") -> #REF! | AL6: =COUNTIFS(#REF!,'Requirement List'!$B5,#REF!,Q$1,#REF!,"Week 17") -> #REF! | AM6: =COUNTIFS(#REF!,'Requirement List'!$B5,#REF!,Q$1,#REF!,"Week 18") -> #REF!
A7: =ROW()-1 -> 6 | B7: ADCL | C7: Earthwork | E7: 45668 | F7: DPM Earthwork | G7: 1 | H7: 45716 | I7: Mr. Raghu Rama Raju | J7: Mr. Ravindra Varma | K7: - | L7: ADCL-06 | M7: APM & Above
A8: =ROW()-1 -> 7 | B8: ADCL | C8: Structures | E8: 45668 | F8: Sr.Engineer (Structures ) | G8: 14 | H8: 45716 | I8: Mr. Radha Krishna (Consultant) | J8: Mr. Ravindra Varma | K8: ANY-05 | L8: ADCL-07 | M8: APM Below | N8: =COUNTIFS(#REF!,'Requirement List'!$B6,#REF!,"Profile shared with Interviewer") -> #REF! | O8: =COUNTIFS(#REF!,'Requirement List'!$B6,#REF!,"Shortlisted for next round of interview") -> #REF! | P8: =COUNTIFS(#REF!,'Requirement List'!$B6,#REF!,P$1) -> #REF! | Q8: =COUNTIFS(#REF!,'Requirement List'!$B6,#REF!,Q$1) -> #REF! | R8: =COUNTIFS(#REF!,'Requirement List'!$B6,#REF!,R$1) -> #REF! | S8: =COUNTIFS(#REF!,'Requirement List'!$B6,#REF!,"Interview Done",#REF!,"Rejected") -> #REF! | T8: =COUNTIFS(#REF!,'Requirement List'!$B6,#REF!,T$1) -> #REF! | U8: =N8+P8+Q8+R8+S8+T8 -> #REF! | V8: =IF((G8-R8-Q8)<1,0,G8-R8-Q8) -> #REF! | W8: =FLOOR(G8,1) -> 14 | X8: =FLOOR(W8,1) -> 14 | Y8: =X8*3 -> 42 | Z8: =IF(W8-SUM(Q8:R8)<1,0,W8-SUM(Q8:R8)) -> #REF! | AA8: =IF(X8-SUM(P8:R8)<1,0,X8-SUM(P8:R8)) -> #REF! | AB8: =IF(AA8*3-N8<1,0,AA8*3-N8) -> #REF! | AC8: =IF(M8="APM Below",H8-45,IF(M8="APM & Above", H8-60,H8-90)) -> 45671 | AD8: =IFERROR(AC8-5,"NA") -> 45666 | AE8: =IFERROR(AD8-7,"NA") -> 45659 | AF8: =CEILING((AC8-TODAY())/7,1) -> -63 | AG8: =CEILING((AD8-TODAY())/7,1) -> -64 | AH8: =CEILING((AE8-TODAY())/7,1) -> -65 | AI8: =COUNTIFS(#REF!,'Requirement List'!$B6,#REF!,Q$1,#REF!,"Week 14") -> #REF! | AJ8: =COUNTIFS(#REF!,'Requirement List'!$B6,#REF!,Q$1,#REF!,"Week 15") -> #REF! | AK8: =COUNTIFS(#REF!,'Requirement List'!$B6,#REF!,Q$1,#REF!,"Week 16") -> #REF! | AL8: =COUNTIFS(#REF!,'Requirement List'!$B6,#REF!,Q$1,#REF!,"Week 17") -> #REF! | AM8: =COUNTIFS(#REF!,'Requirement List'!$B6,#REF!,Q$1,#REF!,"Week 18") -> #REF!
A9: =ROW()-1 -> 8 | B9: ADCL | C9: Roads | E9: 45668 | F9: Sr.Engineer ( Roads & Miscellaneous ) | G9: 26 | H9: 45716 | I9: Mr. Varaprasad (Consultant) | J9: Mr. Ravindra Varma | K9: ANY-06 | L9: ADCL-08 | M9: APM Below | N9: =COUNTIFS(#REF!,'Requirement List'!$B7,#REF!,"Profile shared with Interviewer") -> #REF! | O9: =COUNTIFS(#REF!,'Requirement List'!$B7,#REF!,"Shortlisted for next round of interview") -> #REF! | P9: =COUNTIFS(#REF!,'Requirement List'!$B7,#REF!,P$1) -> #REF! | Q9: =COUNTIFS(#REF!,'Requirement List'!$B7,#REF!,Q$1) -> #REF! | R9: =COUNTIFS(#REF!,'Requirement List'!$B7,#REF!,R$1) -> #REF! | S9: =COUNTIFS(#REF!,'Requirement List'!$B7,#REF!,"Interview Done",#REF!,"Rejected") -> #REF! | T9: =COUNTIFS(#REF!,'Requirement List'!$B7,#REF!,T$1) -> #REF! | U9: =N9+P9+Q9+R9+S9+T9 -> #REF! | V9: =IF((G9-R9-Q9)<1,0,G9-R9-Q9) -> #REF! | W9: =FLOOR(G9,1) -> 26 | X9: =FLOOR(W9,1) -> 26 | Y9: =X9*3 -> 78 | Z9: =IF(W9-SUM(Q9:R9)<1,0,W9-SUM(Q9:R9)) -> #REF! | AA9: =IF(X9-SUM(P9:R9)<1,0,X9-SUM(P9:R9)) -> #REF! | AB9: =IF(AA9*3-N9<1,0,AA9*3-N9) -> #REF! | AC9: =IF(M9="APM Below",H9-45,IF(M9="APM & Above", H9-60,H9-90)) -> 45671 | AD9: =IFERROR(AC9-5,"NA") -> 45666 | AE9: =IFERROR(AD9-7,"NA") -> 45659 | AF9: =CEILING((AC9-TODAY())/7,1) -> -63 | AG9: =CEILING((AD9-TODAY())/7,1) -> -64 | AH9: =CEILING((AE9-TODAY())/7,1) -> -65 | AI9: =COUNTIFS(#REF!,'Requirement List'!$B7,#REF!,Q$1,#REF!,"Week 14") -> #REF! | AJ9: =COUNTIFS(#REF!,'Requirement List'!$B7,#REF!,Q$1,#REF!,"Week 15") -> #REF! | AK9: =COUNTIFS(#REF!,'Requirement List'!$B7,#REF!,Q$1,#REF!,"Week 16") -> #REF! | AL9: =COUNTIFS(#REF!,'Requirement List'!$B7,#REF!,Q$1,#REF!,"Week 17") -> #REF! | AM9: =COUNTIFS(#REF!,'Requirement List'!$B7,#REF!,Q$1,#REF!,"Week 18") -> #REF!
A10: =ROW()-1 -> 9 | B10: ADCL | C10: Structures | E10: 45668 | F10: Engineers ( Structures ) | G10: 18 | H10: 45716 | I10: Mr. Radha Krishna (Consultant) | J10: Mr. Ravindra Varma | K10: ANY-07 | L10: ADCL-09 | M10: APM Below | N10: =COUNTIFS(#REF!,'Requirement List'!$B8,#REF!,"Profile shared with Interviewer") -> #REF! | O10: =COUNTIFS(#REF!,'Requirement List'!$B8,#REF!,"Shortlisted for next round of interview") -> #REF! | P10: =COUNTIFS(#REF!,'Requirement List'!$B8,#REF!,P$1) -> #REF! | Q10: =COUNTIFS(#REF!,'Requirement List'!$B8,#REF!,Q$1) -> #REF! | R10: =COUNTIFS(#REF!,'Requirement List'!$B8,#REF!,R$1) -> #REF! | S10: =COUNTIFS(#REF!,'Requirement List'!$B8,#REF!,"Interview Done",#REF!,"Rejected") -> #REF! | T10: =COUNTIFS(#REF!,'Requirement List'!$B8,#REF!,T$1) -> #REF! | U10: =N10+P10+Q10+R10+S10+T10 -> #REF! | V10: =IF((G10-R10-Q10)<1,0,G10-R10-Q10) -> #REF! | W10: =FLOOR(G10,1) -> 18 | X10: =FLOOR(W10,1) -> 18 | Y10: =X10*3 -> 54 | Z10: =IF(W10-SUM(Q10:R10)<1,0,W10-SUM(Q10:R10)) -> #REF! | AA10: =IF(X10-SUM(P10:R10)<1,0,X10-SUM(P10:R10)) -> #REF! | AB10: =IF(AA10*3-N10<1,0,AA10*3-N10) -> #REF! | AC10: =IF(M10="APM Below",H10-45,IF(M10="APM & Above", H10-60,H10-90)) -> 45671 | AD10: =IFERROR(AC10-5,"NA") -> 45666 | AE10: =IFERROR(AD10-7,"NA") -> 45659 | AF10: =CEILING((AC10-TODAY())/7,1) -> -63 | AG10: =CEILING((AD10-TODAY())/7,1) -> -64 | AH10: =CEILING((AE10-TODAY())/7,1) -> -65 | AI10: =COUNTIFS(#REF!,'Requirement List'!$B8,#REF!,Q$1,#REF!,"Week 14") -> #REF! | AJ10: =COUNTIFS(#REF!,'Requirement List'!$B8,#REF!,Q$1,#REF!,"Week 15") -> #REF! | AK10: =COUNTIFS(#REF!,'Requirement List'!$B8,#REF!,Q$1,#REF!,"Week 16") -> #REF! | AL10: =COUNTIFS(#REF!,'Requirement List'!$B8,#REF!,Q$1,#REF!,"Week 17") -> #REF! | AM10: =COUNTIFS(#REF!,'Requirement List'!$B8,#REF!,Q$1,#REF!,"Week 18") -> #REF!
A11: =ROW()-1 -> 10 | B11: ADCL | C11: Roads | E11: 45668 | F11: Engineers ( Roads ) | G11: 18 | H11: 45716 | I11: Mr. Madhusudhan Reddy | J11: Mr. Ravindra Varma | K11: ANY-08 | L11: ADCL-10 | M11: APM Below | N11: =COUNTIFS(#REF!,'Requirement List'!$B9,#REF!,"Profile shared with Interviewer") -> #REF! | O11: =COUNTIFS(#REF!,'Requirement List'!$B9,#REF!,"Shortlisted for next round of interview") -> #REF! | P11: =COUNTIFS(#REF!,'Requirement List'!$B9,#REF!,P$1) -> #REF! | Q11: =COUNTIFS(#REF!,'Requirement List'!$B9,#REF!,Q$1) -> #REF! | R11: =COUNTIFS(#REF!,'Requirement List'!$B9,#REF!,R$1) -> #REF! | S11: =COUNTIFS(#REF!,'Requirement List'!$B9,#REF!,"Interview Done",#REF!,"Rejected") -> #REF! | T11: =COUNTIFS(#REF!,'Requirement List'!$B9,#REF!,T$1) -> #REF! | U11: =N11+P11+Q11+R11+S11+T11 -> #REF! | V11: =IF((G11-R11-Q11)<1,0,G11-R11-Q11) -> #REF! | W11: =FLOOR(G11,1) -> 18 | X11: =FLOOR(W11,1) -> 18 | Y11: =X11*3 -> 54 | Z11: =IF(W11-SUM(Q11:R11)<1,0,W11-SUM(Q11:R11)) -> #REF! | AA11: =IF(X11-SUM(P11:R11)<1,0,X11-SUM(P11:R11)) -> #REF! | AB11: =IF(AA11*3-N11<1,0,AA11*3-N11) -> #REF! | AC11: =IF(M11="APM Below",H11-45,IF(M11="APM & Above", H11-60,H11-90)) -> 45671 | AD11: =IFERROR(AC11-5,"NA") -> 45666 | AE11: =IFERROR(AD11-7,"NA") -> 45659 | AF11: =CEILING((AC11-TODAY())/7,1) -> -63 | AG11: =CEILING((AD11-TODAY())/7,1) -> -64 | AH11: =CEILING((AE11-TODAY())/7,1) -> -65 | AI11: =COUNTIFS(#REF!,'Requirement List'!$B9,#REF!,Q$1,#REF!,"Week 14") -> #REF! | AJ11: =COUNTIFS(#REF!,'Requirement List'!$B9,#REF!,Q$1,#REF!,"Week 15") -> #REF! | AK11: =COUNTIFS(#REF!,'Requirement List'!$B9,#REF!,Q$1,#REF!,"Week 16") -> #REF! | AL11: =COUNTIFS(#REF!,'Requirement List'!$B9,#REF!,Q$1,#REF!,"Week 17") -> #REF! | AM11: =COUNTIFS(#REF!,'Requirement List'!$B9,#REF!,Q$1,#REF!,"Week 18") -> #REF!
A12: =ROW()-1 -> 11 | B12: ADCL | C12: Structures | E12: 45668 | F12: Jr.Engineer ( structures) | G12: 14 | H12: 45716 | I12: Mr. Radha Krishna (Consultant) | J12: Mr. Ravindra Varma | K12: ANY-09 | L12: ADCL-11 | M12: APM Below | N12: =COUNTIFS(#REF!,'Requirement List'!$B10,#REF!,"Profile shared with Interviewer") -> #REF! | O12: =COUNTIFS(#REF!,'Requirement List'!$B10,#REF!,"Shortlisted for next round of interview") -> #REF! | P12: =COUNTIFS(#REF!,'Requirement List'!$B10,#REF!,P$1) -> #REF! | Q12: =COUNTIFS(#REF!,'Requirement List'!$B10,#REF!,Q$1) -> #REF! | R12: =COUNTIFS(#REF!,'Requirement List'!$B10,#REF!,R$1) -> #REF! | S12: =COUNTIFS(#REF!,'Requirement List'!$B10,#REF!,"Interview Done",#REF!,"Rejected") -> #REF! | T12: =COUNTIFS(#REF!,'Requirement List'!$B10,#REF!,T$1) -> #REF! | U12: =N12+P12+Q12+R12+S12+T12 -> #REF! | V12: =IF((G12-R12-Q12)<1,0,G12-R12-Q12) -> #REF! | W12: =FLOOR(G12,1) -> 14 | X12: =FLOOR(W12,1) -> 14 | Y12: =X12*3 -> 42 | Z12: =IF(W12-SUM(Q12:R12)<1,0,W12-SUM(Q12:R12)) -> #REF! | AA12: =IF(X12-SUM(P12:R12)<1,0,X12-SUM(P12:R12)) -> #REF! | AB12: =IF(AA12*3-N12<1,0,AA12*3-N12) -> #REF! | AC12: =IF(M12="APM Below",H12-45,IF(M12="APM & Above", H12-60,H12-90)) -> 45671 | AD12: =IFERROR(AC12-5,"NA") -> 45666 | AE12: =IFERROR(AD12-7,"NA") -> 45659 | AF12: =CEILING((AC12-TODAY())/7,1) -> -63 | AG12: =CEILING((AD12-TODAY())/7,1) -> -64 | AH12: =CEILING((AE12-TODAY())/7,1) -> -65 | AI12: =COUNTIFS(#REF!,'Requirement List'!$B10,#REF!,Q$1,#REF!,"Week 14") -> #REF! | AJ12: =COUNTIFS(#REF!,'Requirement List'!$B10,#REF!,Q$1,#REF!,"Week 15") -> #REF! | AK12: =COUNTIFS(#REF!,'Requirement List'!$B10,#REF!,Q$1,#REF!,"Week 16") -> #REF! | AL12: =COUNTIFS(#REF!,'Requirement List'!$B10,#REF!,Q$1,#REF!,"Week 17") -> #REF! | AM12: =COUNTIFS(#REF!,'Requirement List'!$B10,#REF!,Q$1,#REF!,"Week 18") -> #REF!
A13: =ROW()-1 -> 12 | B13: ADCL | C13: Roads | E13: 45668 | F13: Jr. Engineer ( Roads ) | G13: 14 | H13: 45716 | I13: Mr. Madhusudhan Reddy | J13: Mr. Ravindra Varma | K13: ANY-10 | L13: ADCL-12 | M13: APM Below | N13: =COUNTIFS(#REF!,'Requirement List'!$B11,#REF!,"Profile shared with Interviewer") -> #REF! | O13: =COUNTIFS(#REF!,'Requirement List'!$B11,#REF!,"Shortlisted for next round of interview") -> #REF! | P13: =COUNTIFS(#REF!,'Requirement List'!$B11,#REF!,P$1) -> #REF! | Q13: =COUNTIFS(#REF!,'Requirement List'!$B11,#REF!,Q$1) -> #REF! | R13: =COUNTIFS(#REF!,'Requirement List'!$B11,#REF!,R$1) -> #REF! | S13: =COUNTIFS(#REF!,'Requirement List'!$B11,#REF!,"Interview Done",#REF!,"Rejected") -> #REF! | T13: =COUNTIFS(#REF!,'Requirement List'!$B11,#REF!,T$1) -> #REF! | U13: =N13+P13+Q13+R13+S13+T13 -> #REF! | V13: =IF((G13-R13-Q13)<1,0,G13-R13-Q13) -> #REF! | W13: =FLOOR(G13,1) -> 14 | X13: =FLOOR(W13,1) -> 14 | Y13: =X13*3 -> 42 | Z13: =IF(W13-SUM(Q13:R13)<1,0,W13-SUM(Q13:R13)) -> #REF! | AA13: =IF(X13-SUM(P13:R13)<1,0,X13-SUM(P13:R13)) -> #REF! | AB13: =IF(AA13*3-N13<1,0,AA13*3-N13) -> #REF! | AC13: =IF(M13="APM Below",H13-45,IF(M13="APM & Above", H13-60,H13-90)) -> 45671 | AD13: =IFERROR(AC13-5,"NA") -> 45666 | AE13: =IFERROR(AD13-7,"NA") -> 45659 | AF13: =CEILING((AC13-TODAY())/7,1) -> -63 | AG13: =CEILING((AD13-TODAY())/7,1) -> -64 | AH13: =CEILING((AE13-TODAY())/7,1) -> -65 | AI13: =COUNTIFS(#REF!,'Requirement List'!$B11,#REF!,Q$1,#REF!,"Week 14") -> #REF! | AJ13: =COUNTIFS(#REF!,'Requirement List'!$B11,#REF!,Q$1,#REF!,"Week 15") -> #REF! | AK13: =COUNTIFS(#REF!,'Requirement List'!$B11,#REF!,Q$1,#REF!,"Week 16") -> #REF! | AL13: =COUNTIFS(#REF!,'Requirement List'!$B11,#REF!,Q$1,#REF!,"Week 17") -> #REF! | AM13: =COUNTIFS(#REF!,'Requirement List'!$B11,#REF!,Q$1,#REF!,"Week 18") -> #REF!
A14: =ROW()-1 -> 13 | B14: ADCL | E14: 45668 | F14: Surveyors | G14: 28 | H14: 45716 | I14: Mr. Swaroop (Consultant) | J14: Mr. Srinivas | K14: ANY-11 | L14: ADCL-13 | M14: APM Below | N14: =COUNTIFS(#REF!,'Requirement List'!$B12,#REF!,"Profile shared with Interviewer") -> #REF! | O14: =COUNTIFS(#REF!,'Requirement List'!$B12,#REF!,"Shortlisted for next round of interview") -> #REF! | P14: =COUNTIFS(#REF!,'Requirement List'!$B12,#REF!,P$1) -> #REF! | Q14: =COUNTIFS(#REF!,'Requirement List'!$B12,#REF!,Q$1) -> #REF! | R14: =COUNTIFS(#REF!,'Requirement List'!$B12,#REF!,R$1) -> #REF! | S14: =COUNTIFS(#REF!,'Requirement List'!$B12,#REF!,"Interview Done",#REF!,"Rejected") -> #REF! | T14: =COUNTIFS(#REF!,'Requirement List'!$B12,#REF!,T$1) -> #REF! | U14: =N14+P14+Q14+R14+S14+T14 -> #REF! | V14: =IF((G14-R14-Q14)<1,0,G14-R14-Q14) -> #REF! | W14: =FLOOR(G14,1) -> 28 | X14: =FLOOR(W14,1) -> 28 | Y14: =X14*3 -> 84 | Z14: =IF(W14-SUM(Q14:R14)<1,0,W14-SUM(Q14:R14)) -> #REF! | AA14: =IF(X14-SUM(P14:R14)<1,0,X14-SUM(P14:R14)) -> #REF! | AB14: =IF(AA14*3-N14<1,0,AA14*3-N14) -> #REF! | AC14: =IF(M14="APM Below",H14-45,IF(M14="APM & Above", H14-60,H14-90)) -> 45671 | AD14: =IFERROR(AC14-5,"NA") -> 45666 | AE14: =IFERROR(AD14-7,"NA") -> 45659 | AF14: =CEILING((AC14-TODAY())/7,1) -> -63 | AG14: =CEILING((AD14-TODAY())/7,1) -> -64 | AH14: =CEILING((AE14-TODAY())/7,1) -> -65 | AI14: =COUNTIFS(#REF!,'Requirement List'!$B12,#REF!,Q$1,#REF!,"Week 14") -> #REF! | AJ14: =COUNTIFS(#REF!,'Requirement List'!$B12,#REF!,Q$1,#REF!,"Week 15") -> #REF! | AK14: =COUNTIFS(#REF!,'Requirement List'!$B12,#REF!,Q$1,#REF!,"Week 16") -> #REF! | AL14: =COUNTIFS(#REF!,'Requirement List'!$B12,#REF!,Q$1,#REF!,"Week 17") -> #REF! | AM14: =COUNTIFS(#REF!,'Requirement List'!$B12,#REF!,Q$1,#REF!,"Week 18") -> #REF!
A15: =ROW()-1 -> 14 | B15: ADCL | C15: Safety | E15: 45668 | F15: Safety Executives | G15: 14 | H15: 45747 | I15: Mr. Palem Krishna Reddy | J15: Mr. Venu | K15: ANY-49 | L15: ADCL-14 | M15: APM Below | N15: =COUNTIFS(#REF!,'Requirement List'!$B47,#REF!,"Profile shared with Interviewer") -> #REF! | O15: =COUNTIFS(#REF!,'Requirement List'!$B47,#REF!,"Shortlisted for next round of interview") -> #REF! | P15: =COUNTIFS(#REF!,'Requirement List'!$B47,#REF!,P$1) -> #REF! | Q15: =COUNTIFS(#REF!,'Requirement List'!$B47,#REF!,Q$1) -> #REF! | R15: =COUNTIFS(#REF!,'Requirement List'!$B47,#REF!,R$1) -> #REF! | S15: =COUNTIFS(#REF!,'Requirement List'!$B47,#REF!,"Interview Done",#REF!,"Rejected") -> #REF! | T15: =COUNTIFS(#REF!,'Requirement List'!$B47,#REF!,T$1) -> #REF! | U15: =N15+P15+Q15+R15+S15+T15 -> #REF! | V15: =IF((G15-R15-Q15)<1,0,G15-R15-Q15) -> #REF! | W15: =FLOOR(G15,1) -> 14 | X15: =FLOOR(W15,1) -> 14 | Y15: =X15*3 -> 42 | Z15: =IF(W15-SUM(Q15:R15)<1,0,W15-SUM(Q15:R15)) -> #REF! | AA15: =IF(X15-SUM(P15:R15)<1,0,X15-SUM(P15:R15)) -> #REF! | AB15: =IF(AA15*3-N15<1,0,AA15*3-N15) -> #REF! | AC15: =IF(M15="APM Below",H15-45,IF(M15="APM & Above", H15-60,H15-90)) -> 45702 | AD15: =IFERROR(AC15-5,"NA") -> 45697 | AE15: =IFERROR(AD15-7,"NA") -> 45690 | AF15: =CEILING((AC15-TODAY())/7,1) -> -58 | AG15: =CEILING((AD15-TODAY())/7,1) -> -59 | AH15: =CEILING((AE15-TODAY())/7,1) -> -60 | AI15: =COUNTIFS(#REF!,'Requirement List'!$B47,#REF!,Q$1,#REF!,"Week 14") -> #REF! | AJ15: =COUNTIFS(#REF!,'Requirement List'!$B47,#REF!,Q$1,#REF!,"Week 15") -> #REF! | AK15: =COUNTIFS(#REF!,'Requirement List'!$B47,#REF!,Q$1,#REF!,"Week 16") -> #REF! | AL15: =COUNTIFS(#REF!,'Requirement List'!$B47,#REF!,Q$1,#REF!,"Week 17") -> #REF! | AM15: =COUNTIFS(#REF!,'Requirement List'!$B47,#REF!,Q$1,#REF!,"Week 18") -> #REF!
A16: =ROW()-1 -> 15 | B16: ADCL | C16: Safety | E16: 45668 | F16: Safety Officers | G16: 14 | H16: 45716 | I16: Mr. Palem Krishna Reddy | J16: Mr. Venu | K16: ANY-13 | L16: ADCL-15 | M16: APM Below | N16: =COUNTIFS(#REF!,'Requirement List'!$B13,#REF!,"Profile shared with Interviewer") -> #REF! | O16: =COUNTIFS(#REF!,'Requirement List'!$B13,#REF!,"Shortlisted for next round of interview") -> #REF! | P16: =COUNTIFS(#REF!,'Requirement List'!$B13,#REF!,P$1) -> #REF! | Q16: =COUNTIFS(#REF!,'Requirement List'!$B13,#REF!,Q$1) -> #REF! | R16: =COUNTIFS(#REF!,'Requirement List'!$B13,#REF!,R$1) -> #REF! | S16: =COUNTIFS(#REF!,'Requirement List'!$B13,#REF!,"Interview Done",#REF!,"Rejected") -> #REF! | T16: =COUNTIFS(#REF!,'Requirement List'!$B13,#REF!,T$1) -> #REF! | U16: =N16+P16+Q16+R16+S16+T16 -> #REF! | V16: =IF((G16-R16-Q16)<1,0,G16-R16-Q16) -> #REF! | W16: =FLOOR(G16,1) -> 14 | X16: =FLOOR(W16,1) -> 14 | Y16: =X16*3 -> 42 | Z16: =IF(W16-SUM(Q16:R16)<1,0,W16-SUM(Q16:R16)) -> #REF! | AA16: =IF(X16-SUM(P16:R16)<1,0,X16-SUM(P16:R16)) -> #REF! | AB16: =IF(AA16*3-N16<1,0,AA16*3-N16) -> #REF! | AC16: =IF(M16="APM Below",H16-45,IF(M16="APM & Above", H16-60,H16-90)) -> 45671 | AD16: =IFERROR(AC16-5,"NA") -> 45666 | AE16: =IFERROR(AD16-7,"NA") -> 45659 | AF16: =CEILING((AC16-TODAY())/7,1) -> -63 | AG16: =CEILING((AD16-TODAY())/7,1) -> -64 | AH16: =CEILING((AE16-TODAY())/7,1) -> -65 | AI16: =COUNTIFS(#REF!,'Requirement List'!$B13,#REF!,Q$1,#REF!,"Week 14") -> #REF! | AJ16: =COUNTIFS(#REF!,'Requirement List'!$B13,#REF!,Q$1,#REF!,"Week 15") -> #REF! | AK16: =COUNTIFS(#REF!,'Requirement List'!$B13,#REF!,Q$1,#REF!,"Week 16") -> #REF! | AL16: =COUNTIFS(#REF!,'Requirement List'!$B13,#REF!,Q$1,#REF!,"Week 17") -> #REF! | AM16: =COUNTIFS(#REF!,'Requirement List'!$B13,#REF!,Q$1,#REF!,"Week 18") -> #REF!
A17: =ROW()-1 -> 16 | B17: ADCL | C17: QC | E17: 45668 | F17: Manager/Asst Manager ( QC ) | G17: 5 | H17: 45716 | I17: Mr. Rudra Murthy G | J17: Mr. Ravindra Varma | K17: ANY-14 | L17: ADCL-16 | M17: APM & Above | N17: =COUNTIFS(#REF!,'Requirement List'!$B14,#REF!,"Profile shared with Interviewer") -> #REF! | O17: =COUNTIFS(#REF!,'Requirement List'!$B14,#REF!,"Shortlisted for next round of interview") -> #REF! | P17: =COUNTIFS(#REF!,'Requirement List'!$B14,#REF!,P$1) -> #REF! | Q17: =COUNTIFS(#REF!,'Requirement List'!$B14,#REF!,Q$1) -> #REF! | R17: =COUNTIFS(#REF!,'Requirement List'!$B14,#REF!,R$1) -> #REF! | S17: =COUNTIFS(#REF!,'Requirement List'!$B14,#REF!,"Interview Done",#REF!,"Rejected") -> #REF! | T17: =COUNTIFS(#REF!,'Requirement List'!$B14,#REF!,T$1) -> #REF! | U17: =N17+P17+Q17+R17+S17+T17 -> #REF! | V17: =IF((G17-R17-Q17)<1,0,G17-R17-Q17) -> #REF! | W17: =FLOOR(G17,1) -> 5 | X17: =FLOOR(W17,1) -> 5 | Y17: =X17*3 -> 15 | Z17: =IF(W17-SUM(Q17:R17)<1,0,W17-SUM(Q17:R17)) -> #REF! | AA17: =IF(X17-SUM(P17:R17)<1,0,X17-SUM(P17:R17)) -> #REF! | AB17: =IF(AA17*3-N17<1,0,AA17*3-N17) -> #REF! | AC17: =IF(M17="APM Below",H17-45,IF(M17="APM & Above", H17-60,H17-90)) -> 45656 | AD17: =IFERROR(AC17-5,"NA") -> 45651 | AE17: =IFERROR(AD17-7,"NA") -> 45644 | AF17: =CEILING((AC17-TODAY())/7,1) -> -65 | AG17: =CEILING((AD17-TODAY())/7,1) -> -66 | AH17: =CEILING((AE17-TODAY())/7,1) -> -67 | AI17: =COUNTIFS(#REF!,'Requirement List'!$B14,#REF!,Q$1,#REF!,"Week 14") -> #REF! | AJ17: =COUNTIFS(#REF!,'Requirement List'!$B14,#REF!,Q$1,#REF!,"Week 15") -> #REF! | AK17: =COUNTIFS(#REF!,'Requirement List'!$B14,#REF!,Q$1,#REF!,"Week 16") -> #REF! | AL17: =COUNTIFS(#REF!,'Requirement List'!$B14,#REF!,Q$1,#REF!,"Week 17") -> #REF! | AM17: =COUNTIFS(#REF!,'Requirement List'!$B14,#REF!,Q$1,#REF!,"Week 18") -> #REF!
A18: =ROW()-1 -> 17 | B18: ADCL | C18: QC | E18: 45668 | F18: Sr.Engineer (QC) | G18: 10 | H18: 45716 | I18: Mr. Rudra Murthy G | J18: Mr. Ravindra Varma | K18: ANY-15 | L18: ADCL-17 | M18: APM Below | N18: =COUNTIFS(#REF!,'Requirement List'!$B15,#REF!,"Profile shared with Interviewer") -> #REF! | O18: =COUNTIFS(#REF!,'Requirement List'!$B15,#REF!,"Shortlisted for next round of interview") -> #REF! | P18: =COUNTIFS(#REF!,'Requirement List'!$B15,#REF!,P$1) -> #REF! | Q18: =COUNTIFS(#REF!,'Requirement List'!$B15,#REF!,Q$1) -> #REF! | R18: =COUNTIFS(#REF!,'Requirement List'!$B15,#REF!,R$1) -> #REF! | S18: =COUNTIFS(#REF!,'Requirement List'!$B15,#REF!,"Interview Done",#REF!,"Rejected") -> #REF! | T18: =COUNTIFS(#REF!,'Requirement List'!$B15,#REF!,T$1) -> #REF! | U18: =N18+P18+Q18+R18+S18+T18 -> #REF! | V18: =IF((G18-R18-Q18)<1,0,G18-R18-Q18) -> #REF! | W18: =FLOOR(G18,1) -> 10 | X18: =FLOOR(W18,1) -> 10 | Y18: =X18*3 -> 30 | Z18: =IF(W18-SUM(Q18:R18)<1,0,W18-SUM(Q18:R18)) -> #REF! | AA18: =IF(X18-SUM(P18:R18)<1,0,X18-SUM(P18:R18)) -> #REF! | AB18: =IF(AA18*3-N18<1,0,AA18*3-N18) -> #REF! | AC18: =IF(M18="APM Below",H18-45,IF(M18="APM & Above", H18-60,H18-90)) -> 45671 | AD18: =IFERROR(AC18-5,"NA") -> 45666 | AE18: =IFERROR(AD18-7,"NA") -> 45659 | AF18: =CEILING((AC18-TODAY())/7,1) -> -63 | AG18: =CEILING((AD18-TODAY())/7,1) -> -64 | AH18: =CEILING((AE18-TODAY())/7,1) -> -65 | AI18: =COUNTIFS(#REF!,'Requirement List'!$B15,#REF!,Q$1,#REF!,"Week 14") -> #REF! | AJ18: =COUNTIFS(#REF!,'Requirement List'!$B15,#REF!,Q$1,#REF!,"Week 15") -> #REF! | AK18: =COUNTIFS(#REF!,'Requirement List'!$B15,#REF!,Q$1,#REF!,"Week 16") -> #REF! | AL18: =COUNTIFS(#REF!,'Requirement List'!$B15,#REF!,Q$1,#REF!,"Week 17") -> #REF! | AM18: =COUNTIFS(#REF!,'Requirement List'!$B15,#REF!,Q$1,#REF!,"Week 18") -> #REF!
A19: =ROW()-1 -> 18 | B19: ADCL | C19: QC | E19: 45668 | F19: Engineer/Asst Engineer - QC | G19: 23 | H19: 45716 | I19: Mr. Rudra Murthy G | J19: Mr. Ravindra Varma | K19: ANY-16 | L19: ADCL-18 | M19: APM Below | N19: =COUNTIFS(#REF!,'Requirement List'!$B16,#REF!,"Profile shared with Interviewer") -> #REF! | O19: =COUNTIFS(#REF!,'Requirement List'!$B16,#REF!,"Shortlisted for next round of interview") -> #REF! | P19: =COUNTIFS(#REF!,'Requirement List'!$B16,#REF!,P$1) -> #REF! | Q19: =COUNTIFS(#REF!,'Requirement List'!$B16,#REF!,Q$1) -> #REF! | R19: =COUNTIFS(#REF!,'Requirement List'!$B16,#REF!,R$1) -> #REF! | S19: =COUNTIFS(#REF!,'Requirement List'!$B16,#REF!,"Interview Done",#REF!,"Rejected") -> #REF! | T19: =COUNTIFS(#REF!,'Requirement List'!$B16,#REF!,T$1) -> #REF! | U19: =N19+P19+Q19+R19+S19+T19 -> #REF! | V19: =IF((G19-R19-Q19)<1,0,G19-R19-Q19) -> #REF! | W19: =FLOOR(G19,1) -> 23 | X19: =FLOOR(W19,1) -> 23 | Y19: =X19*3 -> 69 | Z19: =IF(W19-SUM(Q19:R19)<1,0,W19-SUM(Q19:R19)) -> #REF! | AA19: =IF(X19-SUM(P19:R19)<1,0,X19-SUM(P19:R19)) -> #REF! | AB19: =IF(AA19*3-N19<1,0,AA19*3-N19) -> #REF! | AC19: =IF(M19="APM Below",H19-45,IF(M19="APM & Above", H19-60,H19-90)) -> 45671 | AD19: =IFERROR(AC19-5,"NA") -> 45666 | AE19: =IFERROR(AD19-7,"NA") -> 45659 | AF19: =CEILING((AC19-TODAY())/7,1) -> -63 | AG19: =CEILING((AD19-TODAY())/7,1) -> -64 | AH19: =CEILING((AE19-TODAY())/7,1) -> -65 | AI19: =COUNTIFS(#REF!,'Requirement List'!$B16,#REF!,Q$1,#REF!,"Week 14") -> #REF! | AJ19: =COUNTIFS(#REF!,'Requirement List'!$B16,#REF!,Q$1,#REF!,"Week 15") -> #REF! | AK19: =COUNTIFS(#REF!,'Requirement List'!$B16,#REF!,Q$1,#REF!,"Week 16") -> #REF! | AL19: =COUNTIFS(#REF!,'Requirement List'!$B16,#REF!,Q$1,#REF!,"Week 17") -> #REF! | AM19: =COUNTIFS(#REF!,'Requirement List'!$B16,#REF!,Q$1,#REF!,"Week 18") -> #REF!
A20: =ROW()-1 -> 19 | B20: ADCL | C20: QC | E20: 45668 | F20: Technicians | G20: 18 | H20: 45716 | I20: Mr. Rudra Murthy G | J20: Mr. Ravindra Varma | K20: ANY-17 | L20: ADCL-19 | M20: APM Below | N20: =COUNTIFS(#REF!,'Requirement List'!$B17,#REF!,"Profile shared with Interviewer") -> #REF! | O20: =COUNTIFS(#REF!,'Requirement List'!$B17,#REF!,"Shortlisted for next round of interview") -> #REF! | P20: =COUNTIFS(#REF!,'Requirement List'!$B17,#REF!,P$1) -> #REF! | Q20: =COUNTIFS(#REF!,'Requirement List'!$B17,#REF!,Q$1) -> #REF! | R20: =COUNTIFS(#REF!,'Requirement List'!$B17,#REF!,R$1) -> #REF! | S20: =COUNTIFS(#REF!,'Requirement List'!$B17,#REF!,"Interview Done",#REF!,"Rejected") -> #REF! | T20: =COUNTIFS(#REF!,'Requirement List'!$B17,#REF!,T$1) -> #REF! | U20: =N20+P20+Q20+R20+S20+T20 -> #REF! | V20: =IF((G20-R20-Q20)<1,0,G20-R20-Q20) -> #REF! | W20: =FLOOR(G20,1) -> 18 | X20: =FLOOR(W20,1) -> 18 | Y20: =X20*3 -> 54 | Z20: =IF(W20-SUM(Q20:R20)<1,0,W20-SUM(Q20:R20)) -> #REF! | AA20: =IF(X20-SUM(P20:R20)<1,0,X20-SUM(P20:R20)) -> #REF! | AB20: =IF(AA20*3-N20<1,0,AA20*3-N20) -> #REF! | AC20: =IF(M20="APM Below",H20-45,IF(M20="APM & Above", H20-60,H20-90)) -> 45671 | AD20: =IFERROR(AC20-5,"NA") -> 45666 | AE20: =IFERROR(AD20-7,"NA") -> 45659 | AF20: =CEILING((AC20-TODAY())/7,1) -> -63 | AG20: =CEILING((AD20-TODAY())/7,1) -> -64 | AH20: =CEILING((AE20-TODAY())/7,1) -> -65 | AI20: =COUNTIFS(#REF!,'Requirement List'!$B17,#REF!,Q$1,#REF!,"Week 14") -> #REF! | AJ20: =COUNTIFS(#REF!,'Requirement List'!$B17,#REF!,Q$1,#REF!,"Week 15") -> #REF! | AK20: =COUNTIFS(#REF!,'Requirement List'!$B17,#REF!,Q$1,#REF!,"Week 16") -> #REF! | AL20: =COUNTIFS(#REF!,'Requirement List'!$B17,#REF!,Q$1,#REF!,"Week 17") -> #REF! | AM20: =COUNTIFS(#REF!,'Requirement List'!$B17,#REF!,Q$1,#REF!,"Week 18") -> #REF!
A21: =ROW()-1 -> 20 | B21: ADCL | C21: Planning & QS | E21: 45668 | F21: DGM ( Planning & QS ) | G21: 1 | H21: 45716 | I21: Mr. Subash | J21: Mr. Ravindra Varma | K21: ANY-18 | L21: ADCL-20 | M21: APM & Above | N21: =COUNTIFS(#REF!,'Requirement List'!$B18,#REF!,"Profile shared with Interviewer") -> #REF! | O21: =COUNTIFS(#REF!,'Requirement List'!$B18,#REF!,"Shortlisted for next round of interview") -> #REF! | P21: =COUNTIFS(#REF!,'Requirement List'!$B18,#REF!,P$1) -> #REF! | Q21: =COUNTIFS(#REF!,'Requirement List'!$B18,#REF!,Q$1) -> #REF! | R21: =COUNTIFS(#REF!,'Requirement List'!$B18,#REF!,R$1) -> #REF! | S21: =COUNTIFS(#REF!,'Requirement List'!$B18,#REF!,"Interview Done",#REF!,"Rejected") -> #REF! | T21: =COUNTIFS(#REF!,'Requirement List'!$B18,#REF!,T$1) -> #REF! | U21: =N21+P21+Q21+R21+S21+T21 -> #REF! | V21: =IF((G21-R21-Q21)<1,0,G21-R21-Q21) -> #REF! | W21: =FLOOR(G21,1) -> 1 | X21: =FLOOR(W21,1) -> 1 | Y21: =X21*3 -> 3 | Z21: =IF(W21-SUM(Q21:R21)<1,0,W21-SUM(Q21:R21)) -> #REF! | AA21: =IF(X21-SUM(P21:R21)<1,0,X21-SUM(P21:R21)) -> #REF! | AB21: =IF(AA21*3-N21<1,0,AA21*3-N21) -> #REF! | AC21: =IF(M21="APM Below",H21-45,IF(M21="APM & Above", H21-60,H21-90)) -> 45656 | AD21: =IFERROR(AC21-5,"NA") -> 45651 | AE21: =IFERROR(AD21-7,"NA") -> 45644 | AF21: =CEILING((AC21-TODAY())/7,1) -> -65 | AG21: =CEILING((AD21-TODAY())/7,1) -> -66 | AH21: =CEILING((AE21-TODAY())/7,1) -> -67 | AI21: =COUNTIFS(#REF!,'Requirement List'!$B18,#REF!,Q$1,#REF!,"Week 14") -> #REF! | AJ21: =COUNTIFS(#REF!,'Requirement List'!$B18,#REF!,Q$1,#REF!,"Week 15") -> #REF! | AK21: =COUNTIFS(#REF!,'Requirement List'!$B18,#REF!,Q$1,#REF!,"Week 16") -> #REF! | AL21: =COUNTIFS(#REF!,'Requirement List'!$B18,#REF!,Q$1,#REF!,"Week 17") -> #REF! | AM21: =COUNTIFS(#REF!,'Requirement List'!$B18,#REF!,Q$1,#REF!,"Week 18") -> #REF!
A22: =ROW()-1 -> 21 | B22: ADCL | C22: Planning & QS | E22: 45668 | F22: Planning & QS Manager | G22: 8 | H22: 45716 | I22: Mr. Subash | J22: Mr. Ravindra Varma | K22: ANY-19 | L22: ADCL-21 | M22: APM & Above | N22: =COUNTIFS(#REF!,'Requirement List'!$B19,#REF!,"Profile shared with Interviewer") -> #REF! | O22: =COUNTIFS(#REF!,'Requirement List'!$B19,#REF!,"Shortlisted for next round of interview") -> #REF! | P22: =COUNTIFS(#REF!,'Requirement List'!$B19,#REF!,P$1) -> #REF! | Q22: =COUNTIFS(#REF!,'Requirement List'!$B19,#REF!,Q$1) -> #REF! | R22: =COUNTIFS(#REF!,'Requirement List'!$B19,#REF!,R$1) -> #REF! | S22: =COUNTIFS(#REF!,'Requirement List'!$B19,#REF!,"Interview Done",#REF!,"Rejected") -> #REF! | T22: =COUNTIFS(#REF!,'Requirement List'!$B19,#REF!,T$1) -> #REF! | U22: =N22+P22+Q22+R22+S22+T22 -> #REF! | V22: =IF((G22-R22-Q22)<1,0,G22-R22-Q22) -> #REF! | W22: =FLOOR(G22,1) -> 8 | X22: =FLOOR(W22,1) -> 8 | Y22: =X22*3 -> 24 | Z22: =IF(W22-SUM(Q22:R22)<1,0,W22-SUM(Q22:R22)) -> #REF! | AA22: =IF(X22-SUM(P22:R22)<1,0,X22-SUM(P22:R22)) -> #REF! | AB22: =IF(AA22*3-N22<1,0,AA22*3-N22) -> #REF! | AC22: =IF(M22="APM Below",H22-45,IF(M22="APM & Above", H22-60,H22-90)) -> 45656 | AD22: =IFERROR(AC22-5,"NA") -> 45651 | AE22: =IFERROR(AD22-7,"NA") -> 45644 | AF22: =CEILING((AC22-TODAY())/7,1) -> -65 | AG22: =CEILING((AD22-TODAY())/7,1) -> -66 | AH22: =CEILING((AE22-TODAY())/7,1) -> -67 | AI22: =COUNTIFS(#REF!,'Requirement List'!$B19,#REF!,Q$1,#REF!,"Week 14") -> #REF! | AJ22: =COUNTIFS(#REF!,'Requirement List'!$B19,#REF!,Q$1,#REF!,"Week 15") -> #REF! | AK22: =COUNTIFS(#REF!,'Requirement List'!$B19,#REF!,Q$1,#REF!,"Week 16") -> #REF! | AL22: =COUNTIFS(#REF!,'Requirement List'!$B19,#REF!,Q$1,#REF!,"Week 17") -> #REF! | AM22: =COUNTIFS(#REF!,'Requirement List'!$B19,#REF!,Q$1,#REF!,"Week 18") -> #REF!
A23: =ROW()-1 -> 22 | B23: ADCL | C23: Planning & QS | E23: 45668 | F23: Sr.Engineer ( QS ) | G23: 18 | H23: 45716 | I23: Mr. Subash | J23: Mr. Ravindra Varma | K23: ANY-20 | L23: ADCL-22 | M23: APM Below | N23: =COUNTIFS(#REF!,'Requirement List'!$B20,#REF!,"Profile shared with Interviewer") -> #REF! | O23: =COUNTIFS(#REF!,'Requirement List'!$B20,#REF!,"Shortlisted for next round of interview") -> #REF! | P23: =COUNTIFS(#REF!,'Requirement List'!$B20,#REF!,P$1) -> #REF! | Q23: =COUNTIFS(#REF!,'Requirement List'!$B20,#REF!,Q$1) -> #REF! | R23: =COUNTIFS(#REF!,'Requirement List'!$B20,#REF!,R$1) -> #REF! | S23: =COUNTIFS(#REF!,'Requirement List'!$B20,#REF!,"Interview Done",#REF!,"Rejected") -> #REF! | T23: =COUNTIFS(#REF!,'Requirement List'!$B20,#REF!,T$1) -> #REF! | U23: =N23+P23+Q23+R23+S23+T23 -> #REF! | V23: =IF((G23-R23-Q23)<1,0,G23-R23-Q23) -> #REF! | W23: =FLOOR(G23,1) -> 18 | X23: =FLOOR(W23,1) -> 18 | Y23: =X23*3 -> 54 | Z23: =IF(W23-SUM(Q23:R23)<1,0,W23-SUM(Q23:R23)) -> #REF! | AA23: =IF(X23-SUM(P23:R23)<1,0,X23-SUM(P23:R23)) -> #REF! | AB23: =IF(AA23*3-N23<1,0,AA23*3-N23) -> #REF! | AC23: =IF(M23="APM Below",H23-45,IF(M23="APM & Above", H23-60,H23-90)) -> 45671 | AD23: =IFERROR(AC23-5,"NA") -> 45666 | AE23: =IFERROR(AD23-7,"NA") -> 45659 | AF23: =CEILING((AC23-TODAY())/7,1) -> -63 | AG23: =CEILING((AD23-TODAY())/7,1) -> -64 | AH23: =CEILING((AE23-TODAY())/7,1) -> -65 | AI23: =COUNTIFS(#REF!,'Requirement List'!$B20,#REF!,Q$1,#REF!,"Week 14") -> #REF! | AJ23: =COUNTIFS(#REF!,'Requirement List'!$B20,#REF!,Q$1,#REF!,"Week 15") -> #REF! | AK23: =COUNTIFS(#REF!,'Requirement List'!$B20,#REF!,Q$1,#REF!,"Week 16") -> #REF! | AL23: =COUNTIFS(#REF!,'Requirement List'!$B20,#REF!,Q$1,#REF!,"Week 17") -> #REF! | AM23: =COUNTIFS(#REF!,'Requirement List'!$B20,#REF!,Q$1,#REF!,"Week 18") -> #REF!
A24: =ROW()-1 -> 23 | B24: ADCL | C24: Planning & QS | E24: 45668 | F24: Asst Engineer ( QS ) | G24: 20 | H24: 45716 | I24: Mr. Subash | J24: Mr. Ravindra Varma | K24: ANY-21 | L24: ADCL-23 | M24: APM Below | N24: =COUNTIFS(#REF!,'Requirement List'!$B21,#REF!,"Profile shared with Interviewer") -> #REF! | O24: =COUNTIFS(#REF!,'Requirement List'!$B21,#REF!,"Shortlisted for next round of interview") -> #REF! | P24: =COUNTIFS(#REF!,'Requirement List'!$B21,#REF!,P$1) -> #REF! | Q24: =COUNTIFS(#REF!,'Requirement List'!$B21,#REF!,Q$1) -> #REF! | R24: =COUNTIFS(#REF!,'Requirement List'!$B21,#REF!,R$1) -> #REF! | S24: =COUNTIFS(#REF!,'Requirement List'!$B21,#REF!,"Interview Done",#REF!,"Rejected") -> #REF! | T24: =COUNTIFS(#REF!,'Requirement List'!$B21,#REF!,T$1) -> #REF! | U24: =N24+P24+Q24+R24+S24+T24 -> #REF! | V24: =IF((G24-R24-Q24)<1,0,G24-R24-Q24) -> #REF! | W24: =FLOOR(G24,1) -> 20 | X24: =FLOOR(W24,1) -> 20 | Y24: =X24*3 -> 60 | Z24: =IF(W24-SUM(Q24:R24)<1,0,W24-SUM(Q24:R24)) -> #REF! | AA24: =IF(X24-SUM(P24:R24)<1,0,X24-SUM(P24:R24)) -> #REF! | AB24: =IF(AA24*3-N24<1,0,AA24*3-N24) -> #REF! | AC24: =IF(M24="APM Below",H24-45,IF(M24="APM & Above", H24-60,H24-90)) -> 45671 | AD24: =IFERROR(AC24-5,"NA") -> 45666 | AE24: =IFERROR(AD24-7,"NA") -> 45659 | AF24: =CEILING((AC24-TODAY())/7,1) -> -63 | AG24: =CEILING((AD24-TODAY())/7,1) -> -64 | AH24: =CEILING((AE24-TODAY())/7,1) -> -65 | AI24: =COUNTIFS(#REF!,'Requirement List'!$B21,#REF!,Q$1,#REF!,"Week 14") -> #REF! | AJ24: =COUNTIFS(#REF!,'Requirement List'!$B21,#REF!,Q$1,#REF!,"Week 15") -> #REF! | AK24: =COUNTIFS(#REF!,'Requirement List'!$B21,#REF!,Q$1,#REF!,"Week 16") -> #REF! | AL24: =COUNTIFS(#REF!,'Requirement List'!$B21,#REF!,Q$1,#REF!,"Week 17") -> #REF! | AM24: =COUNTIFS(#REF!,'Requirement List'!$B21,#REF!,Q$1,#REF!,"Week 18") -> #REF!
A25: =ROW()-1 -> 24 | B25: ADCL | C25: Stores | E25: 45668 | F25: Sr. Manager ( Stores & Procurement ) | G25: 1 | H25: 45716 | I25: Mr. Y Srinivas Rao | J25: Mr. Ravindra Varma | K25: ANY-23 | L25: ADCL-24 | M25: APM & Above | N25: =COUNTIFS(#REF!,'Requirement List'!$B22,#REF!,"Profile shared with Interviewer") -> #REF! | O25: =COUNTIFS(#REF!,'Requirement List'!$B22,#REF!,"Shortlisted for next round of interview") -> #REF! | P25: =COUNTIFS(#REF!,'Requirement List'!$B22,#REF!,P$1) -> #REF! | Q25: =COUNTIFS(#REF!,'Requirement List'!$B22,#REF!,Q$1) -> #REF! | R25: =COUNTIFS(#REF!,'Requirement List'!$B22,#REF!,R$1) -> #REF! | S25: =COUNTIFS(#REF!,'Requirement List'!$B22,#REF!,"Interview Done",#REF!,"Rejected") -> #REF! | T25: =COUNTIFS(#REF!,'Requirement List'!$B22,#REF!,T$1) -> #REF! | U25: =N25+P25+Q25+R25+S25+T25 -> #REF! | V25: =IF((G25-R25-Q25)<1,0,G25-R25-Q25) -> #REF! | W25: =FLOOR(G25,1) -> 1 | X25: =FLOOR(W25,1) -> 1 | Y25: =X25*3 -> 3 | Z25: =IF(W25-SUM(Q25:R25)<1,0,W25-SUM(Q25:R25)) -> #REF! | AA25: =IF(X25-SUM(P25:R25)<1,0,X25-SUM(P25:R25)) -> #REF! | AB25: =IF(AA25*3-N25<1,0,AA25*3-N25) -> #REF! | AC25: =IF(M25="APM Below",H25-45,IF(M25="APM & Above", H25-60,H25-90)) -> 45656 | AD25: =IFERROR(AC25-5,"NA") -> 45651 | AE25: =IFERROR(AD25-7,"NA") -> 45644 | AF25: =CEILING((AC25-TODAY())/7,1) -> -65 | AG25: =CEILING((AD25-TODAY())/7,1) -> -66 | AH25: =CEILING((AE25-TODAY())/7,1) -> -67 | AI25: =COUNTIFS(#REF!,'Requirement List'!$B22,#REF!,Q$1,#REF!,"Week 14") -> #REF! | AJ25: =COUNTIFS(#REF!,'Requirement List'!$B22,#REF!,Q$1,#REF!,"Week 15") -> #REF! | AK25: =COUNTIFS(#REF!,'Requirement List'!$B22,#REF!,Q$1,#REF!,"Week 16") -> #REF! | AL25: =COUNTIFS(#REF!,'Requirement List'!$B22,#REF!,Q$1,#REF!,"Week 17") -> #REF! | AM25: =COUNTIFS(#REF!,'Requirement List'!$B22,#REF!,Q$1,#REF!,"Week 18") -> #REF!
A26: =ROW()-1 -> 25 | B26: ADCL | C26: Stores | E26: 45668 | F26: Manager Stores | G26: 1 | H26: 45716 | I26: Mr. Y Srinivas Rao | J26: Mr. Ravindra Varma | K26: ANY-24 | L26: ADCL-25 | M26: APM & Above | N26: =COUNTIFS(#REF!,'Requirement List'!$B23,#REF!,"Profile shared with Interviewer") -> #REF! | O26: =COUNTIFS(#REF!,'Requirement List'!$B23,#REF!,"Shortlisted for next round of interview") -> #REF! | P26: =COUNTIFS(#REF!,'Requirement List'!$B23,#REF!,P$1) -> #REF! | Q26: =COUNTIFS(#REF!,'Requirement List'!$B23,#REF!,Q$1) -> #REF! | R26: =COUNTIFS(#REF!,'Requirement List'!$B23,#REF!,R$1) -> #REF! | S26: =COUNTIFS(#REF!,'Requirement List'!$B23,#REF!,"Interview Done",#REF!,"Rejected") -> #REF! | T26: =COUNTIFS(#REF!,'Requirement List'!$B23,#REF!,T$1) -> #REF! | U26: =N26+P26+Q26+R26+S26+T26 -> #REF! | V26: =IF((G26-R26-Q26)<1,0,G26-R26-Q26) -> #REF! | W26: =FLOOR(G26,1) -> 1 | X26: =FLOOR(W26,1) -> 1 | Y26: =X26*3 -> 3 | Z26: =IF(W26-SUM(Q26:R26)<1,0,W26-SUM(Q26:R26)) -> #REF! | AA26: =IF(X26-SUM(P26:R26)<1,0,X26-SUM(P26:R26)) -> #REF! | AB26: =IF(AA26*3-N26<1,0,AA26*3-N26) -> #REF! | AC26: =IF(M26="APM Below",H26-45,IF(M26="APM & Above", H26-60,H26-90)) -> 45656 | AD26: =IFERROR(AC26-5,"NA") -> 45651 | AE26: =IFERROR(AD26-7,"NA") -> 45644 | AF26: =CEILING((AC26-TODAY())/7,1) -> -65 | AG26: =CEILING((AD26-TODAY())/7,1) -> -66 | AH26: =CEILING((AE26-TODAY())/7,1) -> -67 | AI26: =COUNTIFS(#REF!,'Requirement List'!$B23,#REF!,Q$1,#REF!,"Week 14") -> #REF! | AJ26: =COUNTIFS(#REF!,'Requirement List'!$B23,#REF!,Q$1,#REF!,"Week 15") -> #REF! | AK26: =COUNTIFS(#REF!,'Requirement List'!$B23,#REF!,Q$1,#REF!,"Week 16") -> #REF! | AL26: =COUNTIFS(#REF!,'Requirement List'!$B23,#REF!,Q$1,#REF!,"Week 17") -> #REF! | AM26: =COUNTIFS(#REF!,'Requirement List'!$B23,#REF!,Q$1,#REF!,"Week 18") -> #REF!
A27: =ROW()-1 -> 26 | B27: ADCL | C27: Stores | E27: 45668 | F27: Stores Executives | G27: 4 | H27: 45716 | I27: Mr. Y Srinivas Rao | J27: Mr. Ravindra Varma | K27: ANY-25 | L27: ADCL-26 | M27: APM Below | N27: =COUNTIFS(#REF!,'Requirement List'!$B24,#REF!,"Profile shared with Interviewer") -> #REF! | O27: =COUNTIFS(#REF!,'Requirement List'!$B24,#REF!,"Shortlisted for next round of interview") -> #REF! | P27: =COUNTIFS(#REF!,'Requirement List'!$B24,#REF!,P$1) -> #REF! | Q27: =COUNTIFS(#REF!,'Requirement List'!$B24,#REF!,Q$1) -> #REF! | R27: =COUNTIFS(#REF!,'Requirement List'!$B24,#REF!,R$1) -> #REF! | S27: =COUNTIFS(#REF!,'Requirement List'!$B24,#REF!,"Interview Done",#REF!,"Rejected") -> #REF! | T27: =COUNTIFS(#REF!,'Requirement List'!$B24,#REF!,T$1) -> #REF! | U27: =N27+P27+Q27+R27+S27+T27 -> #REF! | V27: =IF((G27-R27-Q27)<1,0,G27-R27-Q27) -> #REF! | W27: =FLOOR(G27,1) -> 4 | X27: =FLOOR(W27,1) -> 4 | Y27: =X27*3 -> 12 | Z27: =IF(W27-SUM(Q27:R27)<1,0,W27-SUM(Q27:R27)) -> #REF! | AA27: =IF(X27-SUM(P27:R27)<1,0,X27-SUM(P27:R27)) -> #REF! | AB27: =IF(AA27*3-N27<1,0,AA27*3-N27) -> #REF! | AC27: =IF(M27="APM Below",H27-45,IF(M27="APM & Above", H27-60,H27-90)) -> 45671 | AD27: =IFERROR(AC27-5,"NA") -> 45666 | AE27: =IFERROR(AD27-7,"NA") -> 45659 | AF27: =CEILING((AC27-TODAY())/7,1) -> -63 | AG27: =CEILING((AD27-TODAY())/7,1) -> -64 | AH27: =CEILING((AE27-TODAY())/7,1) -> -65 | AI27: =COUNTIFS(#REF!,'Requirement List'!$B24,#REF!,Q$1,#REF!,"Week 14") -> #REF! | AJ27: =COUNTIFS(#REF!,'Requirement List'!$B24,#REF!,Q$1,#REF!,"Week 15") -> #REF! | AK27: =COUNTIFS(#REF!,'Requirement List'!$B24,#REF!,Q$1,#REF!,"Week 16") -> #REF! | AL27: =COUNTIFS(#REF!,'Requirement List'!$B24,#REF!,Q$1,#REF!,"Week 17") -> #REF! | AM27: =COUNTIFS(#REF!,'Requirement List'!$B24,#REF!,Q$1,#REF!,"Week 18") -> #REF!
... A32: =ROW()-1 -> 31 | B32: ADCL | C32: Accounts | E32: 45668 | F32: Sr.Accouts Officer | G32: 2 | H32: 45716 | I32: Mr. Sunil/Gangadhar | J32: Mr. Venu | K32: ANY-30 | L32: ADCL-31 | M32: APM Below | N32: =COUNTIFS(#REF!,'Requirement List'!$B29,#REF!,"Profile shared with Interviewer") -> #REF! | O32: =COUNTIFS(#REF!,'Requirement List'!$B29,#REF!,"Shortlisted for next round of interview") -> #REF! | P32: =COUNTIFS(#REF!,'Requirement List'!$B29,#REF!,P$1) -> #REF! | Q32: =COUNTIFS(#REF!,'Requirement List'!$B29,#REF!,Q$1) -> #REF! | R32: =COUNTIFS(#REF!,'Requirement List'!$B29,#REF!,R$1) -> #REF! | S32: =COUNTIFS(#REF!,'Requirement List'!$B29,#REF!,"Interview Done",#REF!,"Rejected") -> #REF! | T32: =COUNTIFS(#REF!,'Requirement List'!$B29,#REF!,T$1) -> #REF! | U32: =N32+P32+Q32+R32+S32+T32 -> #REF! | V32: =IF((G32-R32-Q32)<1,0,G32-R32-Q32) -> #REF! | W32: =FLOOR(G32,1) -> 2 | X32: =FLOOR(W32,1) -> 2 | Y32: =X32*3 -> 6 | Z32: =IF(W32-SUM(Q32:R32)<1,0,W32-SUM(Q32:R32)) -> #REF! | AA32: =IF(X32-SUM(P32:R32)<1,0,X32-SUM(P32:R32)) -> #REF! | AB32: =IF(AA32*3-N32<1,0,AA32*3-N32) -> #REF! | AC32: =IF(M32="APM Below",H32-45,IF(M32="APM & Above", H32-60,H32-90)) -> 45671 | AD32: =IFERROR(AC32-5,"NA") -> 45666 | AE32: =IFERROR(AD32-7,"NA") -> 45659 | AF32: =CEILING((AC32-TODAY())/7,1) -> -63 | AG32: =CEILING((AD32-TODAY())/7,1) -> -64 | AH32: =CEILING((AE32-TODAY())/7,1) -> -65 | AI32: =COUNTIFS(#REF!,'Requirement List'!$B29,#REF!,Q$1,#REF!,"Week 14") -> #REF! | AJ32: =COUNTIFS(#REF!,'Requirement List'!$B29,#REF!,Q$1,#REF!,"Week 15") -> #REF! | AK32: =COUNTIFS(#REF!,'Requirement List'!$B29,#REF!,Q$1,#REF!,"Week 16") -> #REF! | AL32: =COUNTIFS(#REF!,'Requirement List'!$B29,#REF!,Q$1,#REF!,"Week 17") -> #REF! | AM32: =COUNTIFS(#REF!,'Requirement List'!$B29,#REF!,Q$1,#REF!,"Week 18") -> #REF!
A33: =ROW()-1 -> 32 | B33: ADCL | C33: Accounts | E33: 45668 | F33: Accounts Asst | G33: 4 | H33: 45747 | I33: Mr. Sunil/Gangadhar | J33: Mr. Venu | K33: ANY-62 | L33: ADCL-32 | M33: APM Below | N33: =COUNTIFS(#REF!,'Requirement List'!$B59,#REF!,"Profile shared with Interviewer") -> #REF! | O33: =COUNTIFS(#REF!,'Requirement List'!$B59,#REF!,"Shortlisted for next round of interview") -> #REF! | P33: =COUNTIFS(#REF!,'Requirement List'!$B59,#REF!,P$1) -> #REF! | Q33: =COUNTIFS(#REF!,'Requirement List'!$B59,#REF!,Q$1) -> #REF! | R33: =COUNTIFS(#REF!,'Requirement List'!$B59,#REF!,R$1) -> #REF! | S33: =COUNTIFS(#REF!,'Requirement List'!$B59,#REF!,"Interview Done",#REF!,"Rejected") -> #REF! | T33: =COUNTIFS(#REF!,'Requirement List'!$B59,#REF!,T$1) -> #REF! | U33: =N33+P33+Q33+R33+S33+T33 -> #REF! | V33: =IF((G33-R33-Q33)<1,0,G33-R33-Q33) -> #REF! | W33: =FLOOR(G33,1) -> 4 | X33: =FLOOR(W33,1) -> 4 | Y33: =X33*3 -> 12 | Z33: =IF(W33-SUM(Q33:R33)<1,0,W33-SUM(Q33:R33)) -> #REF! | AA33: =IF(X33-SUM(P33:R33)<1,0,X33-SUM(P33:R33)) -> #REF! | AB33: =IF(AA33*3-N33<1,0,AA33*3-N33) -> #REF! | AC33: =IF(M33="APM Below",H33-45,IF(M33="APM & Above", H33-60,H33-90)) -> 45702 | AD33: =IFERROR(AC33-5,"NA") -> 45697 | AE33: =IFERROR(AD33-7,"NA") -> 45690 | AF33: =CEILING((AC33-TODAY())/7,1) -> -58 | AG33: =CEILING((AD33-TODAY())/7,1) -> -59 | AH33: =CEILING((AE33-TODAY())/7,1) -> -60 | AI33: =COUNTIFS(#REF!,'Requirement List'!$B59,#REF!,Q$1,#REF!,"Week 14") -> #REF! | AJ33: =COUNTIFS(#REF!,'Requirement List'!$B59,#REF!,Q$1,#REF!,"Week 15") -> #REF! | AK33: =COUNTIFS(#REF!,'Requirement List'!$B59,#REF!,Q$1,#REF!,"Week 16") -> #REF! | AL33: =COUNTIFS(#REF!,'Requirement List'!$B59,#REF!,Q$1,#REF!,"Week 17") -> #REF! | AM33: =COUNTIFS(#REF!,'Requirement List'!$B59,#REF!,Q$1,#REF!,"Week 18") -> #REF!
A34: =ROW()-1 -> 33 | B34: ADCL | C34: P&M | E34: 45668 | F34: Manager ( P& M) | G34: 2 | H34: 45716 | I34: Mr. Vijaya Rama Raju | J34: Mr. Ravindra Varma | K34: ANY-31 | L34: ADCL-33 | M34: APM & Above | N34: =COUNTIFS(#REF!,'Requirement List'!$B30,#REF!,"Profile shared with Interviewer") -> #REF! | O34: =COUNTIFS(#REF!,'Requirement List'!$B30,#REF!,"Shortlisted for next round of interview") -> #REF! | P34: =COUNTIFS(#REF!,'Requirement List'!$B30,#REF!,P$1) -> #REF! | Q34: =COUNTIFS(#REF!,'Requirement List'!$B30,#REF!,Q$1) -> #REF! | R34: =COUNTIFS(#REF!,'Requirement List'!$B30,#REF!,R$1) -> #REF! | S34: =COUNTIFS(#REF!,'Requirement List'!$B30,#REF!,"Interview Done",#REF!,"Rejected") -> #REF! | T34: =COUNTIFS(#REF!,'Requirement List'!$B30,#REF!,T$1) -> #REF! | U34: =N34+P34+Q34+R34+S34+T34 -> #REF! | V34: =IF((G34-R34-Q34)<1,0,G34-R34-Q34) -> #REF! | W34: =FLOOR(G34,1) -> 2 | X34: =FLOOR(W34,1) -> 2 | Y34: =X34*3 -> 6 | Z34: =IF(W34-SUM(Q34:R34)<1,0,W34-SUM(Q34:R34)) -> #REF! | AA34: =IF(X34-SUM(P34:R34)<1,0,X34-SUM(P34:R34)) -> #REF! | AB34: =IF(AA34*3-N34<1,0,AA34*3-N34) -> #REF! | AC34: =IF(M34="APM Below",H34-45,IF(M34="APM & Above", H34-60,H34-90)) -> 45656 | AD34: =IFERROR(AC34-5,"NA") -> 45651 | AE34: =IFERROR(AD34-7,"NA") -> 45644 | AF34: =CEILING((AC34-TODAY())/7,1) -> -65 | AG34: =CEILING((AD34-TODAY())/7,1) -> -66 | AH34: =CEILING((AE34-TODAY())/7,1) -> -67 | AI34: =COUNTIFS(#REF!,'Requirement List'!$B30,#REF!,Q$1,#REF!,"Week 14") -> #REF! | AJ34: =COUNTIFS(#REF!,'Requirement List'!$B30,#REF!,Q$1,#REF!,"Week 15") -> #REF! | AK34: =COUNTIFS(#REF!,'Requirement List'!$B30,#REF!,Q$1,#REF!,"Week 16") -> #REF! | AL34: =COUNTIFS(#REF!,'Requirement List'!$B30,#REF!,Q$1,#REF!,"Week 17") -> #REF! | AM34: =COUNTIFS(#REF!,'Requirement List'!$B30,#REF!,Q$1,#REF!,"Week 18") -> #REF!
A35: =ROW()-1 -> 34 | B35: ADCL | C35: P&M | E35: 45668 | F35: Sr. Engineer ( P& M) | G35: 4 | H35: 45716 | I35: Mr. Vijaya Rama Raju | J35: Mr. Venu | K35: ANY-32 | L35: ADCL-34 | M35: APM Below | N35: =COUNTIFS(#REF!,'Requirement List'!$B31,#REF!,"Profile shared with Interviewer") -> #REF! | O35: =COUNTIFS(#REF!,'Requirement List'!$B31,#REF!,"Shortlisted for next round of interview") -> #REF! | P35: =COUNTIFS(#REF!,'Requirement List'!$B31,#REF!,P$1) -> #REF! | Q35: =COUNTIFS(#REF!,'Requirement List'!$B31,#REF!,Q$1) -> #REF! | R35: =COUNTIFS(#REF!,'Requirement List'!$B31,#REF!,R$1) -> #REF! | S35: =COUNTIFS(#REF!,'Requirement List'!$B31,#REF!,"Interview Done",#REF!,"Rejected") -> #REF! | T35: =COUNTIFS(#REF!,'Requirement List'!$B31,#REF!,T$1) -> #REF! | U35: =N35+P35+Q35+R35+S35+T35 -> #REF! | V35: =IF((G35-R35-Q35)<1,0,G35-R35-Q35) -> #REF! | W35: =FLOOR(G35,1) -> 4 | X35: =FLOOR(W35,1) -> 4 | Y35: =X35*3 -> 12 | Z35: =IF(W35-SUM(Q35:R35)<1,0,W35-SUM(Q35:R35)) -> #REF! | AA35: =IF(X35-SUM(P35:R35)<1,0,X35-SUM(P35:R35)) -> #REF! | AB35: =IF(AA35*3-N35<1,0,AA35*3-N35) -> #REF! | AC35: =IF(M35="APM Below",H35-45,IF(M35="APM & Above", H35-60,H35-90)) -> 45671 | AD35: =IFERROR(AC35-5,"NA") -> 45666 | AE35: =IFERROR(AD35-7,"NA") -> 45659 | AF35: =CEILING((AC35-TODAY())/7,1) -> -63 | AG35: =CEILING((AD35-TODAY())/7,1) -> -64 | AH35: =CEILING((AE35-TODAY())/7,1) -> -65 | AI35: =COUNTIFS(#REF!,'Requirement List'!$B31,#REF!,Q$1,#REF!,"Week 14") -> #REF! | AJ35: =COUNTIFS(#REF!,'Requirement List'!$B31,#REF!,Q$1,#REF!,"Week 15") -> #REF! | AK35: =COUNTIFS(#REF!,'Requirement List'!$B31,#REF!,Q$1,#REF!,"Week 16") -> #REF! | AL35: =COUNTIFS(#REF!,'Requirement List'!$B31,#REF!,Q$1,#REF!,"Week 17") -> #REF! | AM35: =COUNTIFS(#REF!,'Requirement List'!$B31,#REF!,Q$1,#REF!,"Week 18") -> #REF!
A36: =ROW()-1 -> 35 | B36: ADCL | C36: P&M | E36: 45668 | F36: Engineer ( P& M) | G36: 8 | H36: 45716 | I36: Mr. Vijaya Rama Raju | J36: Mr. Venu | K36: ANY-33 | L36: ADCL-35 | M36: APM Below | N36: =COUNTIFS(#REF!,'Requirement List'!$B32,#REF!,"Profile shared with Interviewer") -> #REF! | O36: =COUNTIFS(#REF!,'Requirement List'!$B32,#REF!,"Shortlisted for next round of interview") -> #REF! | P36: =COUNTIFS(#REF!,'Requirement List'!$B32,#REF!,P$1) -> #REF! | Q36: =COUNTIFS(#REF!,'Requirement List'!$B32,#REF!,Q$1) -> #REF! | R36: =COUNTIFS(#REF!,'Requirement List'!$B32,#REF!,R$1) -> #REF! | S36: =COUNTIFS(#REF!,'Requirement List'!$B32,#REF!,"Interview Done",#REF!,"Rejected") -> #REF! | T36: =COUNTIFS(#REF!,'Requirement List'!$B32,#REF!,T$1) -> #REF! | U36: =N36+P36+Q36+R36+S36+T36 -> #REF! | V36: =IF((G36-R36-Q36)<1,0,G36-R36-Q36) -> #REF! | W36: =FLOOR(G36,1) -> 8 | X36: =FLOOR(W36,1) -> 8 | Y36: =X36*3 -> 24 | Z36: =IF(W36-SUM(Q36:R36)<1,0,W36-SUM(Q36:R36)) -> #REF! | AA36: =IF(X36-SUM(P36:R36)<1,0,X36-SUM(P36:R36)) -> #REF! | AB36: =IF(AA36*3-N36<1,0,AA36*3-N36) -> #REF! | AC36: =IF(M36="APM Below",H36-45,IF(M36="APM & Above", H36-60,H36-90)) -> 45671 | AD36: =IFERROR(AC36-5,"NA") -> 45666 | AE36: =IFERROR(AD36-7,"NA") -> 45659 | AF36: =CEILING((AC36-TODAY())/7,1) -> -63 | AG36: =CEILING((AD36-TODAY())/7,1) -> -64 | AH36: =CEILING((AE36-TODAY())/7,1) -> -65 | AI36: =COUNTIFS(#REF!,'Requirement List'!$B32,#REF!,Q$1,#REF!,"Week 14") -> #REF! | AJ36: =COUNTIFS(#REF!,'Requirement List'!$B32,#REF!,Q$1,#REF!,"Week 15") -> #REF! | AK36: =COUNTIFS(#REF!,'Requirement List'!$B32,#REF!,Q$1,#REF!,"Week 16") -> #REF! | AL36: =COUNTIFS(#REF!,'Requirement List'!$B32,#REF!,Q$1,#REF!,"Week 17") -> #REF! | AM36: =COUNTIFS(#REF!,'Requirement List'!$B32,#REF!,Q$1,#REF!,"Week 18") -> #REF!
A37: =ROW()-1 -> 36 | B37: ADCL | C37: Earthwork | E37: 45668 | F37: Project Manager ( Earthwork) | G37: 1 | H37: 45716 | I37: Mr. Raghu Rama Raju | J37: Mr. Ravindra Varma | K37: ANY-35 | L37: ADCL-36 | M37: APM & Above | N37: =COUNTIFS(#REF!,'Requirement List'!$B33,#REF!,"Profile shared with Interviewer") -> #REF! | O37: =COUNTIFS(#REF!,'Requirement List'!$B33,#REF!,"Shortlisted for next round of interview") -> #REF! | P37: =COUNTIFS(#REF!,'Requirement List'!$B33,#REF!,P$1) -> #REF! | Q37: =COUNTIFS(#REF!,'Requirement List'!$B33,#REF!,Q$1) -> #REF! | R37: =COUNTIFS(#REF!,'Requirement List'!$B33,#REF!,R$1) -> #REF! | S37: =COUNTIFS(#REF!,'Requirement List'!$B33,#REF!,"Interview Done",#REF!,"Rejected") -> #REF! | T37: =COUNTIFS(#REF!,'Requirement List'!$B33,#REF!,T$1) -> #REF! | U37: =N37+P37+Q37+R37+S37+T37 -> #REF! | V37: =IF((G37-R37-Q37)<1,0,G37-R37-Q37) -> #REF! | W37: =FLOOR(G37,1) -> 1 | X37: =FLOOR(W37,1) -> 1 | Y37: =X37*3 -> 3 | Z37: =IF(W37-SUM(Q37:R37)<1,0,W37-SUM(Q37:R37)) -> #REF! | AA37: =IF(X37-SUM(P37:R37)<1,0,X37-SUM(P37:R37)) -> #REF! | AB37: =IF(AA37*3-N37<1,0,AA37*3-N37) -> #REF! | AC37: =IF(M37="APM Below",H37-45,IF(M37="APM & Above", H37-60,H37-90)) -> 45656 | AD37: =IFERROR(AC37-5,"NA") -> 45651 | AE37: =IFERROR(AD37-7,"NA") -> 45644 | AF37: =CEILING((AC37-TODAY())/7,1) -> -65 | AG37: =CEILING((AD37-TODAY())/7,1) -> -66 | AH37: =CEILING((AE37-TODAY())/7,1) -> -67 | AI37: =COUNTIFS(#REF!,'Requirement List'!$B33,#REF!,Q$1,#REF!,"Week 14") -> #REF! | AJ37: =COUNTIFS(#REF!,'Requirement List'!$B33,#REF!,Q$1,#REF!,"Week 15") -> #REF! | AK37: =COUNTIFS(#REF!,'Requirement List'!$B33,#REF!,Q$1,#REF!,"Week 16") -> #REF! | AL37: =COUNTIFS(#REF!,'Requirement List'!$B33,#REF!,Q$1,#REF!,"Week 17") -> #REF! | AM37: =COUNTIFS(#REF!,'Requirement List'!$B33,#REF!,Q$1,#REF!,"Week 18") -> #REF!
A38: =ROW()-1 -> 37 | B38: ADCL | C38: Earthwork | E38: 45668 | F38: Sr.Engineers ( Earthwork ) | G38: 0 | H38: 45716 | I38: Mr. Raghu Rama Raju | J38: Mr. Ravindra Varma | K38: ANY-36 | M38: APM Below | N38: =COUNTIFS(#REF!,'Requirement List'!$B34,#REF!,"Profile shared with Interviewer") -> #REF! | O38: =COUNTIFS(#REF!,'Requirement List'!$B34,#REF!,"Shortlisted for next round of interview") -> #REF! | P38: =COUNTIFS(#REF!,'Requirement List'!$B34,#REF!,P$1) -> #REF! | Q38: =COUNTIFS(#REF!,'Requirement List'!$B34,#REF!,Q$1) -> #REF! | R38: =COUNTIFS(#REF!,'Requirement List'!$B34,#REF!,R$1) -> #REF! | S38: =COUNTIFS(#REF!,'Requirement List'!$B34,#REF!,"Interview Done",#REF!,"Rejected") -> #REF! | T38: =COUNTIFS(#REF!,'Requirement List'!$B34,#REF!,T$1) -> #REF! | U38: =N38+P38+Q38+R38+S38+T38 -> #REF! | V38: =IF((G38-R38-Q38)<1,0,G38-R38-Q38) -> #REF! | W38: =FLOOR(G38,1) -> 0 | X38: =FLOOR(W38,1) -> 0 | Y38: =X38*3 -> 0 | Z38: =IF(W38-SUM(Q38:R38)<1,0,W38-SUM(Q38:R38)) -> #REF! | AA38: =IF(X38-SUM(P38:R38)<1,0,X38-SUM(P38:R38)) -> #REF! | AB38: =IF(AA38*3-N38<1,0,AA38*3-N38) -> #REF! | AC38: =IF(M38="APM Below",H38-45,IF(M38="APM & Above", H38-60,H38-90)) -> 45671 | AD38: =IFERROR(AC38-5,"NA") -> 45666 | AE38: =IFERROR(AD38-7,"NA") -> 45659 | AF38: =CEILING((AC38-TODAY())/7,1) -> -63 | AG38: =CEILING((AD38-TODAY())/7,1) -> -64 | AH38: =CEILING((AE38-TODAY())/7,1) -> -65 | AI38: =COUNTIFS(#REF!,'Requirement List'!$B34,#REF!,Q$1,#REF!,"Week 14") -> #REF! | AJ38: =COUNTIFS(#REF!,'Requirement List'!$B34,#REF!,Q$1,#REF!,"Week 15") -> #REF! | AK38: =COUNTIFS(#REF!,'Requirement List'!$B34,#REF!,Q$1,#REF!,"Week 16") -> #REF! | AL38: =COUNTIFS(#REF!,'Requirement List'!$B34,#REF!,Q$1,#REF!,"Week 17") -> #REF! | AM38: =COUNTIFS(#REF!,'Requirement List'!$B34,#REF!,Q$1,#REF!,"Week 18") -> #REF!
